Workbook

Sheet Notes and calculations
B3: investment | C3: =SUM('2BAS'!C:C) -> 0
B4: v1cap | C4: =SUM('1CAP'!B2:B34) -> 204902.31
B6: Capital stock | C6: =C4/F6 -> 1366015.4 | E6: Gross | F6: 0.15
B8: rorc | C8: =(C4-C3)/C6 -> 0.15
B10: Depreciation
B11: I want a long run growth of: | C11: 0.03
C13: =(C6+C3)-(C6*(1+C11)) -> -40980.461
B15: Depreciation rate | C15: =C13/C6 -> -0.03

Sheet COM
A1: Value
A2: AG
A3: MIN
A4: FBT
A5: TEX
A6: LEATHER
A7: WOOD
A8: PPP
A9: PC
A10: CHM
A11: RUBBER
A12: NMM
... A34: DWE

Sheet IND
A1: Value
A2: AG
A3: MIN
A4: FBT
A5: TEX
A6: LEATHER
A7: WOOD
A8: PPP
A9: PC
A10: CHM
A11: RUBBER
A12: NMM
... A34: DWE

Sheet OCC
A1: Value
A2: EMIRATI
A3: MIGRANTHH
A4: MIGRANTCOMB
A5: COMMUTING

Sheet LELAS
A1: OCC | B1: Value
A2: EMIRATI | B2: 0.15
A3: MIGRANTHH | B3: 0.3
A4: MIGRANTCOMB | B4: 0.3
A5: COMMUTING | B5: 0.6

Sheet 1BAS
A1: COM | B1: SRC | C1: IND | D1: Value
A2: AG | B2: dom | C2: AG | D2: 9.8941912
A3: MIN | B3: dom | C3: AG | D3: 0
A4: FBT | B4: dom | C4: AG | D4: 157.79694
A5: TEX | B5: dom | C5: AG | D5: 1.256591
A6: LEATHER | B6: dom | C6: AG | D6: 0
A7: WOOD | B7: dom | C7: AG | D7: 0
A8: PPP | B8: dom | C8: AG | D8: 0
A9: PC | B9: dom | C9: AG | D9: 13.401128
A10: CHM | B10: dom | C10: AG | D10: 1.3170773
A11: RUBBER | B11: dom | C11: AG | D11: 0
A12: NMM | B12: dom | C12: AG | D12: 0
A13: METAL | B13: dom | C13: AG | D13: 0
... A2179: DWE | B2179: imp | C2179: DWE | D2179: 0

Sheet VCAPSTOCK
A1: IND | B1: Value
A2: AG | B2: ='1CAP'!B2/0.15 -> 2762.1491
A3: MIN | B3: ='1CAP'!B3/0.15 -> 49042.655
A4: FBT | B4: ='1CAP'!B4/0.15 -> 22662.129
A5: TEX | B5: ='1CAP'!B5/0.15 -> 5416.5817
A6: LEATHER | B6: ='1CAP'!B6/0.15 -> 25.404263
A7: WOOD | B7: ='1CAP'!B7/0.15 -> 2051.1572
A8: PPP | B8: ='1CAP'!B8/0.15 -> 5861.0992
A9: PC | B9: ='1CAP'!B9/0.15 -> 12854.701
A10: CHM | B10: ='1CAP'!B10/0.15 -> 16245.114
A11: RUBBER | B11: ='1CAP'!B11/0.15 -> 8015.6187
A12: NMM | B12: ='1CAP'!B12/0.15 -> 5643.5776
A13: METAL | B13: ='1CAP'!B13/0.15 -> 48814.375
... A34: DWE | B34: ='1CAP'!B34/0.15 -> 2.2794893

Sheet VDEP
A1: IND | B1: Value
A2: AG | B2: =VCAPSTOCK!B2*0.0410637168940699 -> 113.42411
A3: MIN | B3: =VCAPSTOCK!B3*0.0410637168940699 -> 2013.8737
A4: FBT | B4: =VCAPSTOCK!B4*0.0410637168940699 -> 930.59127
A5: TEX | B5: =VCAPSTOCK!B5*0.0410637168940699 -> 222.42498
A6: LEATHER | B6: =VCAPSTOCK!B6*0.0410637168940699 -> 1.0431935
A7: WOOD | B7: =VCAPSTOCK!B7*0.0410637168940699 -> 84.228138
A8: PPP | B8: =VCAPSTOCK!B8*0.0410637168940699 -> 240.67852
A9: PC | B9: =VCAPSTOCK!B9*0.0410637168940699 -> 527.86182
A10: CHM | B10: =VCAPSTOCK!B10*0.0410637168940699 -> 667.08477
A11: RUBBER | B11: =VCAPSTOCK!B11*0.0410637168940699 -> 329.1511
A12: NMM | B12: =VCAPSTOCK!B12*0.0410637168940699 -> 231.74627
A13: METAL | B13: =VCAPSTOCK!B13*0.0410637168940699 -> 2004.4997
... A34: DWE | B34: =VCAPSTOCK!B34*0.0410637168940699 -> 0.093604302

Sheet 2BAS Calcs
A1: COM | B1: SRC | C1: Value | K1: COM | L1: SRC | M1: IND | N1: Value
A2: AG | B2: dom | C2: 22.681407 | F2: 0 | G2: 0 | H2: 0 | K2: =OFFSET(A$2,G2,0) -> AG | L2: =OFFSET($V$3,H2,0) -> dom | M2: =OFFSET(A$2,F2,0) -> AG | N2: =SUMIFS(C:C,A:A,K2,B:B,L2)*SUMIFS(U:U,S:S,M2) -> 0.045862901 | P2: Check | Q2: =SUM(N2:N2179)-SUM(C2:C67) -> 0 | S2: IND | T2: Value
A3: MIN | B3: dom | C3: 39.565835 | F3: =F2 -> 0 | G3: =G2+1 -> 1 | H3: 0 | K3: =OFFSET(A$2,G3,0) -> MIN | L3: =OFFSET($V$3,H3,0) -> dom | M3: =OFFSET(A$2,F3,0) -> AG | N3: =SUMIFS(C:C,A:A,K3,B:B,L3)*SUMIFS(U:U,S:S,M3) -> 0.08000403 | S3: AG | T3: ='1CAP'!B2 -> 414.32237 | U3: =T3/SUM($T$3:$T$35) -> 0.0020220483 | V3: dom
A4: FBT | B4: dom | C4: 66.620512 | F4: =F3 -> 0 | G4: =G3+1 -> 2 | H4: 0 | K4: =OFFSET(A$2,G4,0) -> FBT | L4: =OFFSET($V$3,H4,0) -> dom | M4: =OFFSET(A$2,F4,0) -> AG | N4: =SUMIFS(C:C,A:A,K4,B:B,L4)*SUMIFS(U:U,S:S,M4) -> 0.13470989 | S4: MIN | T4: ='1CAP'!B3 -> 7356.3983 | U4: =T4/SUM($T$3:$T$35) -> 0.035901979 | V4: imp
A5: TEX | B5: dom | C5: 347.01645 | F5: =F4 -> 0 | G5: =G4+1 -> 3 | H5: 0 | K5: =OFFSET(A$2,G5,0) -> TEX | L5: =OFFSET($V$3,H5,0) -> dom | M5: =OFFSET(A$2,F5,0) -> AG | N5: =SUMIFS(C:C,A:A,K5,B:B,L5)*SUMIFS(U:U,S:S,M5) -> 0.70168404 | S5: FBT | T5: ='1CAP'!B4 -> 3399.3194 | U5: =T5/SUM($T$3:$T$35) -> 0.016589952
A6: LEATHER | B6: dom | C6: 2.4623657 | F6: =F5 -> 0 | G6: =G5+1 -> 4 | H6: 0 | K6: =OFFSET(A$2,G6,0) -> LEATHER | L6: =OFFSET($V$3,H6,0) -> dom | M6: =OFFSET(A$2,F6,0) -> AG | N6: =SUMIFS(C:C,A:A,K6,B:B,L6)*SUMIFS(U:U,S:S,M6) -> 0.0049790224 | S6: TEX | T6: ='1CAP'!B5 -> 812.48725 | U6: =T6/SUM($T$3:$T$35) -> 0.0039652421
A7: WOOD | B7: dom | C7: 15.158121 | F7: =F6 -> 0 | G7: =G6+1 -> 5 | H7: 0 | K7: =OFFSET(A$2,G7,0) -> WOOD | L7: =OFFSET($V$3,H7,0) -> dom | M7: =OFFSET(A$2,F7,0) -> AG | N7: =SUMIFS(C:C,A:A,K7,B:B,L7)*SUMIFS(U:U,S:S,M7) -> 0.030650454 | S7: LEATHER | T7: ='1CAP'!B6 -> 3.8106395 | U7: =T7/SUM($T$3:$T$35) -> 1.8597348e-05
A8: PPP | B8: dom | C8: 303.39858 | F8: =F7 -> 0 | G8: =G7+1 -> 6 | H8: 0 | K8: =OFFSET(A$2,G8,0) -> PPP | L8: =OFFSET($V$3,H8,0) -> dom | M8: =OFFSET(A$2,F8,0) -> AG | N8: =SUMIFS(C:C,A:A,K8,B:B,L8)*SUMIFS(U:U,S:S,M8) -> 0.6134866 | S8: WOOD | T8: ='1CAP'!B7 -> 307.67358 | U8: =T8/SUM($T$3:$T$35) -> 0.0015015623
A9: PC | B9: dom | C9: 46.232101 | F9: =F8 -> 0 | G9: =G8+1 -> 7 | H9: 0 | K9: =OFFSET(A$2,G9,0) -> PC | L9: =OFFSET($V$3,H9,0) -> dom | M9: =OFFSET(A$2,F9,0) -> AG | N9: =SUMIFS(C:C,A:A,K9,B:B,L9)*SUMIFS(U:U,S:S,M9) -> 0.093483542 | S9: PPP | T9: ='1CAP'!B8 -> 879.16488 | U9: =T9/SUM($T$3:$T$35) -> 0.0042906539
A10: CHM | B10: dom | C10: 287.89657 | F10: =F9 -> 0 | G10: =G9+1 -> 8 | H10: 0 | K10: =OFFSET(A$2,G10,0) -> CHM | L10: =OFFSET($V$3,H10,0) -> dom | M10: =OFFSET(A$2,F10,0) -> AG | N10: =SUMIFS(C:C,A:A,K10,B:B,L10)*SUMIFS(U:U,S:S,M10) -> 0.58214077 | S10: PC | T10: ='1CAP'!B9 -> 1928.2052 | U10: =T10/SUM($T$3:$T$35) -> 0.0094103636
A11: RUBBER | B11: dom | C11: 450.67429 | F11: =F10 -> 0 | G11: =G10+1 -> 9 | H11: 0 | K11: =OFFSET(A$2,G11,0) -> RUBBER | L11: =OFFSET($V$3,H11,0) -> dom | M11: =OFFSET(A$2,F11,0) -> AG | N11: =SUMIFS(C:C,A:A,K11,B:B,L11)*SUMIFS(U:U,S:S,M11) -> 0.9112852 | S11: CHM | T11: ='1CAP'!B10 -> 2436.7671 | U11: =T11/SUM($T$3:$T$35) -> 0.011892336
A12: NMM | B12: dom | C12: 417.49372 | F12: =F11 -> 0 | G12: =G11+1 -> 10 | H12: 0 | K12: =OFFSET(A$2,G12,0) -> NMM | L12: =OFFSET($V$3,H12,0) -> dom | M12: =OFFSET(A$2,F12,0) -> AG | N12: =SUMIFS(C:C,A:A,K12,B:B,L12)*SUMIFS(U:U,S:S,M12) -> 0.84419247 | S12: RUBBER | T12: ='1CAP'!B11 -> 1202.3428 | U12: =T12/SUM($T$3:$T$35) -> 0.0058678833
A13: METAL | B13: dom | C13: 1221.0969 | F13: =F12 -> 0 | G13: =G12+1 -> 11 | H13: 0 | K13: =OFFSET(A$2,G13,0) -> METAL | L13: =OFFSET($V$3,H13,0) -> dom | M13: =OFFSET(A$2,F13,0) -> AG | N13: =SUMIFS(C:C,A:A,K13,B:B,L13)*SUMIFS(U:U,S:S,M13) -> 2.4691169 | S13: NMM | T13: ='1CAP'!B12 -> 846.53663 | U13: =T13/SUM($T$3:$T$35) -> 0.0041314158
A14: MACH | B14: dom | C14: 1767.4415 | F14: =F13 -> 0 | G14: =G13+1 -> 12 | H14: 0 | K14: =OFFSET(A$2,G14,0) -> MACH | L14: =OFFSET($V$3,H14,0) -> dom | M14: =OFFSET(A$2,F14,0) -> AG | N14: =SUMIFS(C:C,A:A,K14,B:B,L14)*SUMIFS(U:U,S:S,M14) -> 3.5738521 | S14: METAL | T14: ='1CAP'!B13 -> 7322.1563 | U14: =T14/SUM($T$3:$T$35) -> 0.035734865
A15: ELEC | B15: dom | C15: 367.6662 | F15: =F14 -> 0 | G15: =G14+1 -> 13 | H15: 0 | K15: =OFFSET(A$2,G15,0) -> ELEC | L15: =OFFSET($V$3,H15,0) -> dom | M15: =OFFSET(A$2,F15,0) -> AG | N15: =SUMIFS(C:C,A:A,K15,B:B,L15)*SUMIFS(U:U,S:S,M15) -> 0.74343882 | S15: MACH | T15: ='1CAP'!B14 -> 981.83229 | U15: =T15/SUM($T$3:$T$35) -> 0.0047917093
A16: TRNEQUIP | B16: dom | C16: 531.09674 | F16: =F15 -> 0 | G16: =G15+1 -> 14 | H16: 0 | K16: =OFFSET(A$2,G16,0) -> TRNEQUIP | L16: =OFFSET($V$3,H16,0) -> dom | M16: =OFFSET(A$2,F16,0) -> AG | N16: =SUMIFS(C:C,A:A,K16,B:B,L16)*SUMIFS(U:U,S:S,M16) -> 1.0739033 | S16: ELEC | T16: ='1CAP'!B15 -> 685.10684 | U16: =T16/SUM($T$3:$T$35) -> 0.003343578
... A34: DWE | B34: dom | C34: 3.3e-05 | F34: =F33 -> 0 | G34: =G33+1 -> 32 | H34: 0 | K34: =OFFSET(A$2,G34,0) -> DWE | L34: =OFFSET($V$3,H34,0) -> dom | M34: =OFFSET(A$2,F34,0) -> AG | N34: =SUMIFS(C:C,A:A,K34,B:B,L34)*SUMIFS(U:U,S:S,M34) -> 6.6727595e-08 | S34: REC | T34: ='1CAP'!B33 -> 41.618478 | U34: =T34/SUM($T$3:$T$35) -> 0.00020311376
A35: AG | B35: imp | C35: 305.31019 | F35: =F34 -> 0 | G35: =G2 -> 0 | H35: 1 | K35: =OFFSET(A$2,G35,0) -> AG | L35: =OFFSET($V$3,H35,0) -> imp | M35: =OFFSET(A$2,F35,0) -> AG | N35: =SUMIFS(C:C,A:A,K35,B:B,L35)*SUMIFS(U:U,S:S,M35) -> 0.61735197 | S35: DWE | T35: ='1CAP'!B34 -> 0.34192339 | U35: =T35/SUM($T$3:$T$35) -> 1.6687142e-06
A36: MIN | B36: imp | C36: 481.66704 | F36: =F35 -> 0 | G36: =G3 -> 1 | H36: 1 | K36: =OFFSET(A$2,G36,0) -> MIN | L36: =OFFSET($V$3,H36,0) -> imp | M36: =OFFSET(A$2,F36,0) -> AG | N36: =SUMIFS(C:C,A:A,K36,B:B,L36)*SUMIFS(U:U,S:S,M36) -> 0.97395402
A37: FBT | B37: imp | C37: 120.52787 | F37: =F36 -> 0 | G37: =G4 -> 2 | H37: 1 | K37: =OFFSET(A$2,G37,0) -> FBT | L37: =OFFSET($V$3,H37,0) -> imp | M37: =OFFSET(A$2,F37,0) -> AG | N37: =SUMIFS(C:C,A:A,K37,B:B,L37)*SUMIFS(U:U,S:S,M37) -> 0.24371317
A38: TEX | B38: imp | C38: 2365.2408 | F38: =F37 -> 0 | G38: =G5 -> 3 | H38: 1 | K38: =OFFSET(A$2,G38,0) -> TEX | L38: =OFFSET($V$3,H38,0) -> imp | M38: =OFFSET(A$2,F38,0) -> AG | N38: =SUMIFS(C:C,A:A,K38,B:B,L38)*SUMIFS(U:U,S:S,M38) -> 4.7826312
A39: LEATHER | B39: imp | C39: 1232.6913 | F39: =F38 -> 0 | G39: =G6 -> 4 | H39: 1 | K39: =OFFSET(A$2,G39,0) -> LEATHER | L39: =OFFSET($V$3,H39,0) -> imp | M39: =OFFSET(A$2,F39,0) -> AG | N39: =SUMIFS(C:C,A:A,K39,B:B,L39)*SUMIFS(U:U,S:S,M39) -> 2.4925614
A40: WOOD | B40: imp | C40: 22.064272 | F40: =F39 -> 0 | G40: =G7 -> 5 | H40: 1 | K40: =OFFSET(A$2,G40,0) -> WOOD | L40: =OFFSET($V$3,H40,0) -> imp | M40: =OFFSET(A$2,F40,0) -> AG | N40: =SUMIFS(C:C,A:A,K40,B:B,L40)*SUMIFS(U:U,S:S,M40) -> 0.044615025
A41: PPP | B41: imp | C41: 317.72329 | F41: =F40 -> 0 | G41: =G8 -> 6 | H41: 1 | K41: =OFFSET(A$2,G41,0) -> PPP | L41: =OFFSET($V$3,H41,0) -> imp | M41: =OFFSET(A$2,F41,0) -> AG | N41: =SUMIFS(C:C,A:A,K41,B:B,L41)*SUMIFS(U:U,S:S,M41) -> 0.64245186
A42: PC | B42: imp | C42: 80.006462 | F42: =F41 -> 0 | G42: =G9 -> 7 | H42: 1 | K42: =OFFSET(A$2,G42,0) -> PC | L42: =OFFSET($V$3,H42,0) -> imp | M42: =OFFSET(A$2,F42,0) -> AG | N42: =SUMIFS(C:C,A:A,K42,B:B,L42)*SUMIFS(U:U,S:S,M42) -> 0.16177693
A43: CHM | B43: imp | C43: 1096.755 | F43: =F42 -> 0 | G43: =G10 -> 8 | H43: 1 | K43: =OFFSET(A$2,G43,0) -> CHM | L43: =OFFSET($V$3,H43,0) -> imp | M43: =OFFSET(A$2,F43,0) -> AG | N43: =SUMIFS(C:C,A:A,K43,B:B,L43)*SUMIFS(U:U,S:S,M43) -> 2.2176916
A44: RUBBER | B44: imp | C44: 839.96856 | F44: =F43 -> 0 | G44: =G11 -> 9 | H44: 1 | K44: =OFFSET(A$2,G44,0) -> RUBBER | L44: =OFFSET($V$3,H44,0) -> imp | M44: =OFFSET(A$2,F44,0) -> AG | N44: =SUMIFS(C:C,A:A,K44,B:B,L44)*SUMIFS(U:U,S:S,M44) -> 1.698457
A45: NMM | B45: imp | C45: 317.07753 | F45: =F44 -> 0 | G45: =G12 -> 10 | H45: 1 | K45: =OFFSET(A$2,G45,0) -> NMM | L45: =OFFSET($V$3,H45,0) -> imp | M45: =OFFSET(A$2,F45,0) -> AG | N45: =SUMIFS(C:C,A:A,K45,B:B,L45)*SUMIFS(U:U,S:S,M45) -> 0.64114608
A46: METAL | B46: imp | C46: 3968.9031 | F46: =F45 -> 0 | G46: =G13 -> 11 | H46: 1 | K46: =OFFSET(A$2,G46,0) -> METAL | L46: =OFFSET($V$3,H46,0) -> imp | M46: =OFFSET(A$2,F46,0) -> AG | N46: =SUMIFS(C:C,A:A,K46,B:B,L46)*SUMIFS(U:U,S:S,M46) -> 8.0253138
A47: MACH | B47: imp | C47: 15203.962 | F47: =F46 -> 0 | G47: =G14 -> 12 | H47: 1 | K47: =OFFSET(A$2,G47,0) -> MACH | L47: =OFFSET($V$3,H47,0) -> imp | M47: =OFFSET(A$2,F47,0) -> AG | N47: =SUMIFS(C:C,A:A,K47,B:B,L47)*SUMIFS(U:U,S:S,M47) -> 30.743147
... A67: DWE | B67: imp | C67: 3.3e-05 | F67: =F66 -> 0 | G67: =G34 -> 32 | H67: 1 | K67: =OFFSET(A$2,G67,0) -> DWE | L67: =OFFSET($V$3,H67,0) -> imp | M67: =OFFSET(A$2,F67,0) -> AG | N67: =SUMIFS(C:C,A:A,K67,B:B,L67)*SUMIFS(U:U,S:S,M67) -> 6.6727595e-08
F68: =F2+1 -> 1 | G68: =G35 -> 0 | H68: =H2 -> 0 | K68: =OFFSET(A$2,G68,0) -> AG | L68: =OFFSET($V$3,H68,0) -> dom | M68: =OFFSET(A$2,F68,0) -> MIN | N68: =SUMIFS(C:C,A:A,K68,B:B,L68)*SUMIFS(U:U,S:S,M68) -> 0.81430739
F69: =F3+1 -> 1 | G69: =G36 -> 1 | H69: =H3 -> 0 | K69: =OFFSET(A$2,G69,0) -> MIN | L69: =OFFSET($V$3,H69,0) -> dom | M69: =OFFSET(A$2,F69,0) -> MIN | N69: =SUMIFS(C:C,A:A,K69,B:B,L69)*SUMIFS(U:U,S:S,M69) -> 1.4204918
F70: =F4+1 -> 1 | G70: =G37 -> 2 | H70: =H4 -> 0 | K70: =OFFSET(A$2,G70,0) -> FBT | L70: =OFFSET($V$3,H70,0) -> dom | M70: =OFFSET(A$2,F70,0) -> MIN | N70: =SUMIFS(C:C,A:A,K70,B:B,L70)*SUMIFS(U:U,S:S,M70) -> 2.3918082
F71: =F5+1 -> 1 | G71: =G38 -> 3 | H71: =H5 -> 0 | K71: =OFFSET(A$2,G71,0) -> TEX | L71: =OFFSET($V$3,H71,0) -> dom | M71: =OFFSET(A$2,F71,0) -> MIN | N71: =SUMIFS(C:C,A:A,K71,B:B,L71)*SUMIFS(U:U,S:S,M71) -> 12.458577
F72: =F6+1 -> 1 | G72: =G39 -> 4 | H72: =H6 -> 0 | K72: =OFFSET(A$2,G72,0) -> LEATHER | L72: =OFFSET($V$3,H72,0) -> dom | M72: =OFFSET(A$2,F72,0) -> MIN | N72: =SUMIFS(C:C,A:A,K72,B:B,L72)*SUMIFS(U:U,S:S,M72) -> 0.0884038
F73: =F7+1 -> 1 | G73: =G40 -> 5 | H73: =H7 -> 0 | K73: =OFFSET(A$2,G73,0) -> WOOD | L73: =OFFSET($V$3,H73,0) -> dom | M73: =OFFSET(A$2,F73,0) -> MIN | N73: =SUMIFS(C:C,A:A,K73,B:B,L73)*SUMIFS(U:U,S:S,M73) -> 0.54420655
F74: =F8+1 -> 1 | G74: =G41 -> 6 | H74: =H8 -> 0 | K74: =OFFSET(A$2,G74,0) -> PPP | L74: =OFFSET($V$3,H74,0) -> dom | M74: =OFFSET(A$2,F74,0) -> MIN | N74: =SUMIFS(C:C,A:A,K74,B:B,L74)*SUMIFS(U:U,S:S,M74) -> 10.89261
F75: =F9+1 -> 1 | G75: =G42 -> 7 | H75: =H9 -> 0 | K75: =OFFSET(A$2,G75,0) -> PC | L75: =OFFSET($V$3,H75,0) -> dom | M75: =OFFSET(A$2,F75,0) -> MIN | N75: =SUMIFS(C:C,A:A,K75,B:B,L75)*SUMIFS(U:U,S:S,M75) -> 1.6598239
F76: =F10+1 -> 1 | G76: =G43 -> 8 | H76: =H10 -> 0 | K76: =OFFSET(A$2,G76,0) -> CHM | L76: =OFFSET($V$3,H76,0) -> dom | M76: =OFFSET(A$2,F76,0) -> MIN | N76: =SUMIFS(C:C,A:A,K76,B:B,L76)*SUMIFS(U:U,S:S,M76) -> 10.336056
...

Sheet 2BAS
A1: COM | B1: SRC | C1: IND | D1: Value
A2: AG | B2: dom | C2: AG | D2: ='2BAS Calcs'!N2 -> 0.045862901
A3: MIN | B3: dom | C3: AG | D3: ='2BAS Calcs'!N3 -> 0.08000403
A4: FBT | B4: dom | C4: AG | D4: ='2BAS Calcs'!N4 -> 0.13470989
A5: TEX | B5: dom | C5: AG | D5: ='2BAS Calcs'!N5 -> 0.70168404
A6: LEATHER | B6: dom | C6: AG | D6: ='2BAS Calcs'!N6 -> 0.0049790224
A7: WOOD | B7: dom | C7: AG | D7: ='2BAS Calcs'!N7 -> 0.030650454
A8: PPP | B8: dom | C8: AG | D8: ='2BAS Calcs'!N8 -> 0.6134866
A9: PC | B9: dom | C9: AG | D9: ='2BAS Calcs'!N9 -> 0.093483542
A10: CHM | B10: dom | C10: AG | D10: ='2BAS Calcs'!N10 -> 0.58214077
A11: RUBBER | B11: dom | C11: AG | D11: ='2BAS Calcs'!N11 -> 0.9112852
A12: NMM | B12: dom | C12: AG | D12: ='2BAS Calcs'!N12 -> 0.84419247
A13: METAL | B13: dom | C13: AG | D13: ='2BAS Calcs'!N13 -> 2.4691169
... A2179: DWE | B2179: imp | C2179: DWE | D2179: ='2BAS Calcs'!N2179 -> 5.5067569e-11

Sheet 3BAS
A1: COM | B1: SRC | C1: Value
A2: AG | B2: dom | C2: 188.42554
A3: MIN | B3: dom | C3: 39.022699
A4: FBT | B4: dom | C4: 3252.1205
A5: TEX | B5: dom | C5: 354.347
A6: LEATHER | B6: dom | C6: 3.900227
A7: WOOD | B7: dom | C7: 1e-06
A8: PPP | B8: dom | C8: 125.19658
A9: PC | B9: dom | C9: 661.44051
A10: CHM | B10: dom | C10: 527.86509
A11: RUBBER | B11: dom | C11: 2.6051413
A12: NMM | B12: dom | C12: 50.778098
A13: METAL | B13: dom | C13: 22.327325
... A67: DWE | B67: imp | C67: 1e-06

Sheet 4BAS
A1: COM | B1: Value
A2: AG | B2: 13478.352
A3: MIN | B3: 125317.36
A4: FBT | B4: 40267.725
A5: TEX | B5: 18250.608
A6: LEATHER | B6: 11177.055
A7: WOOD | B7: 2027.6278
A8: PPP | B8: 3806.5156
A9: PC | B9: 23605.032
A10: CHM | B10: 44799.938
A11: RUBBER | B11: 11455.931
A12: NMM | B12: 4728.6533
A13: METAL | B13: 129405.85
... A34: DWE | B34: 0

Sheet 5BAS
A1: COM | B1: SRC | C1: Value
A2: AG | B2: dom | C2: 0
A3: MIN | B3: dom | C3: 0
A4: FBT | B4: dom | C4: 0
A5: TEX | B5: dom | C5: 0
A6: LEATHER | B6: dom | C6: 0
A7: WOOD | B7: dom | C7: 0
A8: PPP | B8: dom | C8: 0
A9: PC | B9: dom | C9: 0
A10: CHM | B10: dom | C10: 0
A11: RUBBER | B11: dom | C11: 0
A12: NMM | B12: dom | C12: 0
A13: METAL | B13: dom | C13: 0
... A67: DWE | B67: imp | C67: 0

Sheet 6BAS
A1: COM | B1: SRC | C1: Value
A2: AG | B2: dom | C2: 0
A3: MIN | B3: dom | C3: 0
A4: FBT | B4: dom | C4: 0
A5: TEX | B5: dom | C5: 0
A6: LEATHER | B6: dom | C6: 0
A7: WOOD | B7: dom | C7: 0
A8: PPP | B8: dom | C8: 0
A9: PC | B9: dom | C9: 0
A10: CHM | B10: dom | C10: 0
A11: RUBBER | B11: dom | C11: 0
A12: NMM | B12: dom | C12: 0
A13: METAL | B13: dom | C13: 0
... A67: DWE | B67: imp | C67: 0

Sheet 1TAX
A1: COM | B1: SRC | C1: IND | D1: Value
A2: AG | B2: dom | C2: AG | D2: 0
A3: MIN | B3: dom | C3: AG | D3: 0
A4: FBT | B4: dom | C4: AG | D4: 0
A5: TEX | B5: dom | C5: AG | D5: 0
A6: LEATHER | B6: dom | C6: AG | D6: 0
A7: WOOD | B7: dom | C7: AG | D7: 0
A8: PPP | B8: dom | C8: AG | D8: 0
A9: PC | B9: dom | C9: AG | D9: 0
A10: CHM | B10: dom | C10: AG | D10: 0
A11: RUBBER | B11: dom | C11: AG | D11: 0
A12: NMM | B12: dom | C12: AG | D12: 0
A13: METAL | B13: dom | C13: AG | D13: 0
... A2179: DWE | B2179: imp | C2179: DWE | D2179: 0

Sheet 2TAX
A1: COM | B1: SRC | C1: IND | D1: Value
A2: AG | B2: dom | C2: AG | D2: 0
A3: MIN | B3: dom | C3: AG | D3: 0
A4: FBT | B4: dom | C4: AG | D4: 0
A5: TEX | B5: dom | C5: AG | D5: 0
A6: LEATHER | B6: dom | C6: AG | D6: 0
A7: WOOD | B7: dom | C7: AG | D7: 0
A8: PPP | B8: dom | C8: AG | D8: 0
A9: PC | B9: dom | C9: AG | D9: 0
A10: CHM | B10: dom | C10: AG | D10: 0
A11: RUBBER | B11: dom | C11: AG | D11: 0
A12: NMM | B12: dom | C12: AG | D12: 0
A13: METAL | B13: dom | C13: AG | D13: 0
... A2179: DWE | B2179: imp | C2179: DWE | D2179: 0

Sheet 3TAX
A1: COM | B1: SRC | C1: Value
A2: AG | B2: dom | C2: 0
A3: MIN | B3: dom | C3: 0
A4: FBT | B4: dom | C4: 0
A5: TEX | B5: dom | C5: 0
A6: LEATHER | B6: dom | C6: 0
A7: WOOD | B7: dom | C7: 0
A8: PPP | B8: dom | C8: 0
A9: PC | B9: dom | C9: 0
A10: CHM | B10: dom | C10: 0
A11: RUBBER | B11: dom | C11: 0
A12: NMM | B12: dom | C12: 0
A13: METAL | B13: dom | C13: 0
... A67: DWE | B67: imp | C67: 0

Sheet 4TAX
A1: COM | B1: Value
A2: AG | B2: 0
A3: MIN | B3: 0
A4: FBT | B4: 0
A5: TEX | B5: 0
A6: LEATHER | B6: 0
A7: WOOD | B7: 0
A8: PPP | B8: 0
A9: PC | B9: 0
A10: CHM | B10: 0
A11: RUBBER | B11: 0
A12: NMM | B12: 0
A13: METAL | B13: 0
... A34: DWE | B34: 0

Sheet 5TAX
A1: COM | B1: SRC | C1: Value
A2: AG | B2: dom | C2: 0
A3: MIN | B3: dom | C3: 0
A4: FBT | B4: dom | C4: 0
A5: TEX | B5: dom | C5: 0
A6: LEATHER | B6: dom | C6: 0
A7: WOOD | B7: dom | C7: 0
A8: PPP | B8: dom | C8: 0
A9: PC | B9: dom | C9: 0
A10: CHM | B10: dom | C10: 0
A11: RUBBER | B11: dom | C11: 0
A12: NMM | B12: dom | C12: 0
A13: METAL | B13: dom | C13: 0
... A67: DWE | B67: imp | C67: 0

Sheet 1CAP
A1: IND | B1: Value
A2: AG | B2: 414.32237
A3: MIN | B3: 7356.3983
A4: FBT | B4: 3399.3194
A5: TEX | B5: 812.48725
A6: LEATHER | B6: 3.8106395
A7: WOOD | B7: 307.67358
A8: PPP | B8: 879.16488
A9: PC | B9: 1928.2052
A10: CHM | B10: 2436.7671
A11: RUBBER | B11: 1202.3428
A12: NMM | B12: 846.53663
A13: METAL | B13: 7322.1563
... A34: DWE | B34: 0.34192339

Sheet EMPL
A1: IND | B1: OCC | C1: Value
A2: AG | B2: EMIRATI | C2: 268.12814
A3: MIN | B3: EMIRATI | C3: 245.59549
A4: FBT | B4: EMIRATI | C4: 608.48635
A5: TEX | B5: EMIRATI | C5: 190.51167
A6: LEATHER | B6: EMIRATI | C6: 1.6986218
A7: WOOD | B7: EMIRATI | C7: 143.50388
A8: PPP | B8: EMIRATI | C8: 294.40158
A9: PC | B9: EMIRATI | C9: 58.864261
A10: CHM | B10: EMIRATI | C10: 353.94293
A11: RUBBER | B11: EMIRATI | C11: 159.88783
A12: NMM | B12: EMIRATI | C12: 387.41039
A13: METAL | B13: EMIRATI | C13: 920.91294
... A133: DWE | B133: COMMUTING | C133: 35823.011

Sheet 1LAB
A1: IND | B1: OCC | C1: Value
A2: AG | B2: EMIRATI | C2: 14.240861
A3: MIN | B3: EMIRATI | C3: 90.364734
A4: FBT | B4: EMIRATI | C4: 69.178652
A5: TEX | B5: EMIRATI | C5: 21.659221
A6: LEATHER | B6: EMIRATI | C6: 0.19311588
A7: WOOD | B7: EMIRATI | C7: 16.314918
A8: PPP | B8: EMIRATI | C8: 33.470438
A9: PC | B9: EMIRATI | C9: 6.6922626
A10: CHM | B10: EMIRATI | C10: 40.239678
A11: RUBBER | B11: EMIRATI | C11: 18.177604
A12: NMM | B12: EMIRATI | C12: 44.044585
A13: METAL | B13: EMIRATI | C13: 104.69835
... A133: DWE | B133: COMMUTING | C133: 493.60061

Sheet 1LND
A1: IND | B1: Value
A2: AG | B2: 8.1e-05
A3: MIN | B3: 1e-06
A4: FBT | B4: 7e-06
A5: TEX | B5: 4.8e-05
A6: LEATHER | B6: 6.2e-05
A7: WOOD | B7: 4.7e-05
A8: PPP | B8: 2.7e-05
A9: PC | B9: 9.8e-05
A10: CHM | B10: 6.9e-05
A11: RUBBER | B11: 0.0001
A12: NMM | B12: 3e-06
A13: METAL | B13: 4.8e-05
... A34: DWE | B34: 8.2e-05

Sheet 1PTX
A1: IND | B1: Value
A2: AG | B2: 1e-05
A3: MIN | B3: 1e-05
A4: FBT | B4: 1e-05
A5: TEX | B5: 1e-05
A6: LEATHER | B6: 1e-05
A7: WOOD | B7: 1e-05
A8: PPP | B8: 1e-05
A9: PC | B9: 1e-05
A10: CHM | B10: 1e-05
A11: RUBBER | B11: 1e-05
A12: NMM | B12: 1e-05
A13: METAL | B13: 1e-05
... A34: DWE | B34: 1e-05

Sheet 1OCT
A1: IND | B1: Value
A2: AG | B2: 1e-05
A3: MIN | B3: 1e-05
A4: FBT | B4: 1e-05
A5: TEX | B5: 1e-05
A6: LEATHER | B6: 1e-05
A7: WOOD | B7: 1e-05
A8: PPP | B8: 1e-05
A9: PC | B9: 1e-05
A10: CHM | B10: 1e-05
A11: RUBBER | B11: 1e-05
A12: NMM | B12: 1e-05
A13: METAL | B13: 1e-05
... A34: DWE | B34: 1e-05

Sheet MAKE
A1: COM | B1: IND | C1: Value
A2: AG | B2: AG | C2: 1512.2992
A3: MIN | B3: AG | C3: 0
A4: FBT | B4: AG | C4: 0
A5: TEX | B5: AG | C5: 0
A6: LEATHER | B6: AG | C6: 0
A7: WOOD | B7: AG | C7: 0
A8: PPP | B8: AG | C8: 0
A9: PC | B9: AG | C9: 0
A10: CHM | B10: AG | C10: 0
A11: RUBBER | B11: AG | C11: 0
A12: NMM | B12: AG | C12: 0
A13: METAL | B13: AG | C13: 0
... A1090: DWE | B1090: DWE | C1090: 1945.3419

Sheet 0TAR
A1: COM | B1: Value
A2: AG | B2: 144.4832
A3: MIN | B3: 273.09907
A4: FBT | B4: 470.15579
A5: TEX | B5: 316.85345
A6: LEATHER | B6: 123.97176
A7: WOOD | B7: 25.615143
A8: PPP | B8: 76.334952
A9: PC | B9: 110.92151
A10: CHM | B10: 341.30384
A11: RUBBER | B11: 117.91219
A12: NMM | B12: 78.717072
A13: METAL | B13: 767.68665
... A34: DWE | B34: 0

Sheet SLAB
A1: IND | B1: Value
A2: AG | B2: 2
A3: MIN | B3: 2
A4: FBT | B4: 2
A5: TEX | B5: 2
A6: LEATHER | B6: 2
A7: WOOD | B7: 2
A8: PPP | B8: 2
A9: PC | B9: 2
A10: CHM | B10: 2
A11: RUBBER | B11: 2
A12: NMM | B12: 2
A13: METAL | B13: 2
... A34: DWE | B34: 2

Sheet SCAP
A1: Value
A2: -0.5

Sheet P028
A1: IND | B1: Value
A2: AG | B2: 0.23
A3: MIN | B3: 0.2
A4: FBT | B4: 1.12
A5: TEX | B5: 1.26
A6: LEATHER | B6: 1.26
A7: WOOD | B7: 1.26
A8: PPP | B8: 1.26
A9: PC | B9: 1.26
A10: CHM | B10: 1.26
A11: RUBBER | B11: 1.26
A12: NMM | B12: 1.26
A13: METAL | B13: 1.26
... A34: DWE | B34: 1.26

Sheet 1ARM
A1: COM | B1: Value
A2: AG | B2: 2
A3: MIN | B3: 2
A4: FBT | B4: 2
A5: TEX | B5: 2
A6: LEATHER | B6: 2
A7: WOOD | B7: 2
A8: PPP | B8: 2
A9: PC | B9: 2
A10: CHM | B10: 2
A11: RUBBER | B11: 2
A12: NMM | B12: 2
A13: METAL | B13: 2
... A34: DWE | B34: 2

Sheet SCET
A1: IND | B1: Value
A2: AG | B2: 0.4
A3: MIN | B3: 0.4
A4: FBT | B4: 0.4
A5: TEX | B5: 0.4
A6: LEATHER | B6: 0.4
A7: WOOD | B7: 0.4
A8: PPP | B8: 0.4
A9: PC | B9: 0.4
A10: CHM | B10: 0.4
A11: RUBBER | B11: 0.4
A12: NMM | B12: 0.4
A13: METAL | B13: 0.4
... A34: DWE | B34: 0.4

Sheet 2ARM
A1: COM | B1: Value
A2: AG | B2: 2
A3: MIN | B3: 2
A4: FBT | B4: 2
A5: TEX | B5: 2
A6: LEATHER | B6: 2
A7: WOOD | B7: 2
A8: PPP | B8: 2
A9: PC | B9: 2
A10: CHM | B10: 2
A11: RUBBER | B11: 2
A12: NMM | B12: 2
A13: METAL | B13: 2
... A34: DWE | B34: 2

Sheet 3ARM
A1: COM | B1: Value
A2: AG | B2: 2
A3: MIN | B3: 2
A4: FBT | B4: 2
A5: TEX | B5: 2
A6: LEATHER | B6: 2
A7: WOOD | B7: 2
A8: PPP | B8: 2
A9: PC | B9: 2
A10: CHM | B10: 2
A11: RUBBER | B11: 2
A12: NMM | B12: 2
A13: METAL | B13: 2
... A34: DWE | B34: 2

Sheet P021
A1: Value
A2: -1.15

Sheet XPEL
A1: COM | B1: Value
A2: AG | B2: 1
A3: MIN | B3: 1
A4: FBT | B4: 1
A5: TEX | B5: 1
A6: LEATHER | B6: 1
A7: WOOD | B7: 1
A8: PPP | B8: 1
A9: PC | B9: 1
A10: CHM | B10: 1
A11: RUBBER | B11: 1
A12: NMM | B12: 1
A13: METAL | B13: 1
... A34: DWE | B34: 1

Sheet P018
A1: COM | B1: Value
A2: AG | B2: -4.4
A3: MIN | B3: -5.6
A4: FBT | B4: -4.7
A5: TEX | B5: -6.7
A6: LEATHER | B6: -3.6
A7: WOOD | B7: -3.6
A8: PPP | B8: -3.6
A9: PC | B9: -3.6
A10: CHM | B10: -3.6
A11: RUBBER | B11: -3.6
A12: NMM | B12: -3.6
A13: METAL | B13: -3.6
... A34: DWE | B34: -4

Sheet EXNT
A1: Value
A2: -2

Sheet ITEX
A1: Value
A2: AG
A3: MIN
A4: FBT
A5: TEX
A6: LEATHER
A7: WOOD
A8: PPP
A9: PC
A10: CHM
A11: RUBBER
A12: NMM
... A34: DWE

Sheet ARATIO
A1: COM | B1: Value
A2: AG | B2: 1
A3: MIN | B3: 1
A4: FBT | B4: 1
A5: TEX | B5: 1
A6: LEATHER | B6: 1
A7: WOOD | B7: 1
A8: PPP | B8: 1
A9: PC | B9: 1
A10: CHM | B10: 1
A11: RUBBER | B11: 1
A12: NMM | B12: 1
A13: METAL | B13: 1
... A34: DWE | B34: 1
