Workbook
Name adjFactor: 'Estimating non em split'!$Y$290
Name commuting: Calculations!$C$136
Name lowskillWage: 'Estimating non em split'!$D$216
Name توفير_البيانات___أولي: #REF!
Name توفير_البيانات___أولي: #REF!

Sheet HEADERS
A1: COM | C1: IND | E1: OCC | G1: Calculations for the imported shares | Q1: 1BAS | R1: Check | S1: =SUM(T6:T2183)-SUM('Calculations 2'!C45:AI77) -> -1.6298145e-09 | Z1: Capital shares | AC1: 2BAS | AD1: Check | AE1: =SUM(AF6:AF2183)-SUM('Calculations 2'!CE45:CE77) -> 0 | AI1: 3BAS | AJ1: Check | AK1: =SUM(AK6:AK71)-SUM('Calculations 2'!BY45:CB77) -> 0 | AN1: 4BAS | AQ1: 5BAS | AU1: 6BAS | AY1: 1TAX | BE1: 2TAX | BK1: 3TAX | BP1: 4TAX | BT1: 5TAX | BX1: 0TAR | CA1: 1CAP | CD1: 1LAB | CH1: 1LND | CL1: 1PTX | CP1: 1OCT | CT1: MAKE | CY1: SLAB | DC1: P028 | DG1: 1ARM | DK1: SCET | DP1: 2ARM | DU1: 3ARM | DZ1: P021 | ED1: XPEL | EH1: P018 | EM1: EXNT | EQ1: ITEX
V3: 33
A4: Value | C4: Value | E4: Value | I4: Domestic | J4: Imported | K4: Total | M4: Dom share | N4: Imp share | Q4: COM | R4: SRC | S4: IND | T4: Value | AC4: COM | AD4: SRC | AE4: IND | AF4: Value | AI4: COM | AJ4: SRC | AK4: Value | AN4: COM | AO4: Value | AQ4: COM | AR4: SRC | AS4: Value | AU4: COM | AV4: Value | AY4: COM | AZ4: SRC | BA4: IND | BB4: Value | BE4: COM | BF4: SRC | BG4: IND | BH4: Value | BK4: COM | BL4: SRC | BM4: Value | BP4: COM | BQ4: Value | BT4: COM | BU4: SRC | BV4: Value | BX4: COM | BY4: Value | CA4: IND | CB4: Value | CD4: IND | CE4: OCC | CF4: Value | CH4: IND | CI4: Value | CL4: IND | CM4: Value | CP4: IND | CQ4: Value | CT4: COM | CU4: IND | CV4: Value | CY4: IND | CZ4: Value | DC4: IND | DD4: Value | DG4: COM | DH4: Value | DK4: IND | DL4: Value | DP4: COM | DQ4: Value | DU4: COM | DV4: Value | DZ4: Value | ED4: COM | EE4: Value | EH4: COM | EI4: Value | EM4: Value | EQ4: Value
A6: AG | C6: AG | E6: EMIRATI | H6: AG | I6: {=TRANSPOSE('Calculations 2'!C93:AI93)} -> 1512.2992 | J6: {=TRANSPOSE('Calculations 2'!AJ91:BP91)+TRANSPOSE('Calculations 2'!AJ83:BP83)} -> 20356.806 | K6: {=TRANSPOSE('Calculations 2'!AJ93:BP93)} -> 21869.105 | M6: =I6/$K6 -> 0.069152315 | N6: =J6/$K6 -> 0.93084769 | Q6: AG | R6: dom | S6: AG | T6: =OFFSET('Calculations 2'!$C$45,W6,X6)*OFFSET($M$6,W6,0) -> 9.8941912 | V6: 0 | W6: =MOD(V6,$V$3) -> 0 | X6: =FLOOR(V6/$V$3,1) -> 0 | Z6: AG | AA6: {=TRANSPOSE('Calculations 2'!C82:AI82)/SUM('Calculations 2'!C82:AI82)} -> 0.0016841188 | AC6: AG | AD6: dom | AE6: AG | AF6: =OFFSET('Calculations 2'!$CE$45,W6,0)*OFFSET($AA$6,X6,0)*OFFSET($M$6,W6,) -> 0.038198128 | AI6: AG | AJ6: dom | AK6: =SUM('Calculations 2'!BY45:CB45)*M6 -> 188.42553 | AN6: AG | AO6: {='Calculations 2'!CD45:CD77} -> 13478.352 | AQ6: AG | AR6: dom | AS6: {='Calculations 2'!CC45:CC77*M6:M38} -> 0 | AU6: AG | AV6: 0 | AY6: AG | AZ6: dom | BA6: AG | BB6: 0 | BE6: AG | BF6: dom | BG6: AG | BH6: 0 | BK6: AG | BL6: dom | BM6: 0 | BP6: AG | BQ6: 0 | BT6: AG | BU6: dom | BV6: 0 | BX6: AG | BY6: {=TRANSPOSE('Calculations 2'!AJ83:BP83)} -> 144.4832 | CA6: AG | CB6: {=TRANSPOSE('Calculations 2'!C82:AI82)} -> 414.32237 | CD6: AG | CE6: EMIRATI | CF6: {=TRANSPOSE('Calculations 2'!C78:AI78)} -> 14.240861 | CH6: AG | CI6: 0 | CL6: AG | CM6: 0 | CP6: AG | CQ6: 0 | CT6: AG | CU6: AG | CV6: =OFFSET('Calculations 2'!$AJ$12,W6,X6) -> 1512.2992 | CY6: AG | CZ6: 0.5 | DC6: AG | DD6: 0.23 | DG6: AG | DH6: 2 | DK6: AG | DL6: 0.4 | DP6: AG | DQ6: 2 | DU6: AG | DV6: 2 | DZ6: -1.15 | ED6: AG | EE6: 1 | EH6: AG | EI6: -4.4 | EM6: -2 | EQ6: AG
A7: MIN | C7: MIN | E7: MIGRANTHH | H7: MIN | I7: 11448.729 | J7: 139374.78 | K7: 150823.5 | M7: =I7/$K7 -> 0.075908119 | N7: =J7/$K7 -> 0.92409188 | Q7: MIN | R7: dom | S7: AG | T7: =OFFSET('Calculations 2'!$C$45,W7,X7)*OFFSET($M$6,W7,0) -> 0 | V7: =V6+1 -> 1 | W7: =MOD(V7,$V$3) -> 1 | X7: =FLOOR(V7/$V$3,1) -> 0 | Z7: MIN | AA7: 0.029357277 | AC7: MIN | AD7: dom | AE7: AG | AF7: =OFFSET('Calculations 2'!$CE$45,W7,0)*OFFSET($AA$6,X7,0)*OFFSET($M$6,W7,) -> 0.06663351 | AI7: MIN | AJ7: dom | AK7: =SUM('Calculations 2'!BY46:CB46)*M7 -> 39.022698 | AN7: MIN | AO7: 125317.36 | AQ7: MIN | AR7: dom | AS7: 0 | AU7: MIN | AV7: 0 | AY7: MIN | AZ7: dom | BA7: AG | BB7: 0 | BE7: MIN | BF7: dom | BG7: AG | BH7: 0 | BK7: MIN | BL7: dom | BM7: 0 | BP7: MIN | BQ7: 0 | BT7: MIN | BU7: dom | BV7: 0 | BX7: MIN | BY7: 273.09907 | CA7: MIN | CB7: 7222.3983 | CD7: MIN | CE7: EMIRATI | CF7: 90.364734 | CH7: MIN | CI7: 0 | CL7: MIN | CM7: 0 | CP7: MIN | CQ7: 0 | CT7: MIN | CU7: AG | CV7: =OFFSET('Calculations 2'!$AJ$12,W7,X7) -> 0 | CY7: MIN | CZ7: 0.5 | DC7: MIN | DD7: 0.2 | DG7: MIN | DH7: 2 | DK7: MIN | DL7: 0.4 | DP7: MIN | DQ7: 2 | DU7: MIN | DV7: 2 | ED7: MIN | EE7: 1 | EH7: MIN | EI7: -5.6 | EQ7: MIN
A8: FBT | C8: FBT | E8: MIGRANTCOMB | H8: FBT | I8: 25557.719 | J8: 46238.282 | K8: 71796.001 | M8: =I8/$K8 -> 0.35597691 | N8: =J8/$K8 -> 0.64402309 | Q8: FBT | R8: dom | S8: AG | T8: =OFFSET('Calculations 2'!$C$45,W8,X8)*OFFSET($M$6,W8,0) -> 157.79694 | V8: =V7+1 -> 2 | W8: =MOD(V8,$V$3) -> 2 | X8: =FLOOR(V8/$V$3,1) -> 0 | Z8: FBT | AA8: 0.013820837 | AC8: FBT | AD8: dom | AE8: AG | AF8: =OFFSET('Calculations 2'!$CE$45,W8,0)*OFFSET($AA$6,X8,0)*OFFSET($M$6,W8,) -> 0.1121968 | AI8: FBT | AJ8: dom | AK8: =SUM('Calculations 2'!BY47:CB47)*M8 -> 3252.1205 | AN8: FBT | AO8: 40267.725 | AQ8: FBT | AR8: dom | AS8: 0 | AU8: FBT | AV8: 0 | AY8: FBT | AZ8: dom | BA8: AG | BB8: 0 | BE8: FBT | BF8: dom | BG8: AG | BH8: 0 | BK8: FBT | BL8: dom | BM8: 0 | BP8: FBT | BQ8: 0 | BT8: FBT | BU8: dom | BV8: 0 | BX8: FBT | BY8: 470.15579 | CA8: FBT | CB8: 3400.165 | CD8: FBT | CE8: EMIRATI | CF8: 69.178652 | CH8: FBT | CI8: 0 | CL8: FBT | CM8: 0 | CP8: FBT | CQ8: 0 | CT8: FBT | CU8: AG | CV8: =OFFSET('Calculations 2'!$AJ$12,W8,X8) -> 0 | CY8: FBT | CZ8: 0.5 | DC8: FBT | DD8: 1.12 | DG8: FBT | DH8: 2 | DK8: FBT | DL8: 0.4 | DP8: FBT | DQ8: 2 | DU8: FBT | DV8: 2 | ED8: FBT | EE8: 1 | EH8: FBT | EI8: -4.7 | EQ8: FBT
A9: TEX | C9: TEX | E9: COMMUTING | H9: TEX | I9: 3421.037 | J9: 23317.56 | K9: 26738.597 | M9: =I9/$K9 -> 0.12794378 | N9: =J9/$K9 -> 0.87205622 | Q9: TEX | R9: dom | S9: AG | T9: =OFFSET('Calculations 2'!$C$45,W9,X9)*OFFSET($M$6,W9,0) -> 1.256591 | V9: =V8+1 -> 3 | W9: =MOD(V9,$V$3) -> 3 | X9: =FLOOR(V9/$V$3,1) -> 0 | Z9: TEX | AA9: 0.0033036375 | AC9: TEX | AD9: dom | AE9: AG | AF9: =OFFSET('Calculations 2'!$CE$45,W9,0)*OFFSET($AA$6,X9,0)*OFFSET($M$6,W9,) -> 0.58441687 | AI9: TEX | AJ9: dom | AK9: =SUM('Calculations 2'!BY48:CB48)*M9 -> 354.347 | AN9: TEX | AO9: 18250.608 | AQ9: TEX | AR9: dom | AS9: 0 | AU9: TEX | AV9: 0 | AY9: TEX | AZ9: dom | BA9: AG | BB9: 0 | BE9: TEX | BF9: dom | BG9: AG | BH9: 0 | BK9: TEX | BL9: dom | BM9: 0 | BP9: TEX | BQ9: 0 | BT9: TEX | BU9: dom | BV9: 0 | BX9: TEX | BY9: 316.85345 | CA9: TEX | CB9: 812.752 | CD9: TEX | CE9: EMIRATI | CF9: 21.659221 | CH9: TEX | CI9: 0 | CL9: TEX | CM9: 0 | CP9: TEX | CQ9: 0 | CT9: TEX | CU9: AG | CV9: =OFFSET('Calculations 2'!$AJ$12,W9,X9) -> 0 | CY9: TEX | CZ9: 0.5 | DC9: TEX | DD9: 1.26 | DG9: TEX | DH9: 2 | DK9: TEX | DL9: 0.4 | DP9: TEX | DQ9: 2 | DU9: TEX | DV9: 2 | ED9: TEX | EE9: 1 | EH9: TEX | EI9: -6.7 | EQ9: TEX
A10: LEATHER | C10: LEATHER | H10: LEATHER | I10: 29.598 | J10: 14817.33 | K10: 14846.928 | M10: =I10/$K10 -> 0.0019935437 | N10: =J10/$K10 -> 0.99800646 | Q10: LEATHER | R10: dom | S10: AG | T10: =OFFSET('Calculations 2'!$C$45,W10,X10)*OFFSET($M$6,W10,0) -> 0 | V10: =V9+1 -> 4 | W10: =MOD(V10,$V$3) -> 4 | X10: =FLOOR(V10/$V$3,1) -> 0 | Z10: LEATHER | AA10: 1.549891e-05 | AC10: LEATHER | AD10: dom | AE10: AG | AF10: =OFFSET('Calculations 2'!$CE$45,W10,0)*OFFSET($AA$6,X10,0)*OFFSET($M$6,W10,) -> 0.0041468607 | AI10: LEATHER | AJ10: dom | AK10: =SUM('Calculations 2'!BY49:CB49)*M10 -> 3.900226 | AN10: LEATHER | AO10: 11177.055 | AQ10: LEATHER | AR10: dom | AS10: 0 | AU10: LEATHER | AV10: 0 | AY10: LEATHER | AZ10: dom | BA10: AG | BB10: 0 | BE10: LEATHER | BF10: dom | BG10: AG | BH10: 0 | BK10: LEATHER | BL10: dom | BM10: 0 | BP10: LEATHER | BQ10: 0 | BT10: LEATHER | BU10: dom | BV10: 0 | BX10: LEATHER | BY10: 123.97176 | CA10: LEATHER | CB10: 3.813 | CD10: LEATHER | CE10: EMIRATI | CF10: 0.19311588 | CH10: LEATHER | CI10: 0 | CL10: LEATHER | CM10: 0 | CP10: LEATHER | CQ10: 0 | CT10: LEATHER | CU10: AG | CV10: =OFFSET('Calculations 2'!$AJ$12,W10,X10) -> 0 | CY10: LEATHER | CZ10: 0.5 | DC10: LEATHER | DD10: 1.26 | DG10: LEATHER | DH10: 2 | DK10: LEATHER | DL10: 0.4 | DP10: LEATHER | DQ10: 2 | DU10: LEATHER | DV10: 2 | ED10: LEATHER | EE10: 1 | EH10: LEATHER | EI10: -3.6 | EQ10: LEATHER
A11: WOOD | C11: WOOD | H11: WOOD | I11: 2673.883 | J11: 3892.1263 | K11: 6566.0093 | M11: =I11/$K11 -> 0.40723107 | N11: =J11/$K11 -> 0.59276893 | Q11: WOOD | R11: dom | S11: AG | T11: =OFFSET('Calculations 2'!$C$45,W11,X11)*OFFSET($M$6,W11,0) -> 0 | V11: =V10+1 -> 5 | W11: =MOD(V11,$V$3) -> 5 | X11: =FLOOR(V11/$V$3,1) -> 0 | Z11: WOOD | AA11: 0.0012514282 | AC11: WOOD | AD11: dom | AE11: AG | AF11: =OFFSET('Calculations 2'!$CE$45,W11,0)*OFFSET($AA$6,X11,0)*OFFSET($M$6,W11,) -> 0.025528021 | AI11: WOOD | AJ11: dom | AK11: =SUM('Calculations 2'!BY50:CB50)*M11 -> 0 | AN11: WOOD | AO11: 2027.6278 | AQ11: WOOD | AR11: dom | AS11: 0 | AU11: WOOD | AV11: 0 | AY11: WOOD | AZ11: dom | BA11: AG | BB11: 0 | BE11: WOOD | BF11: dom | BG11: AG | BH11: 0 | BK11: WOOD | BL11: dom | BM11: 0 | BP11: WOOD | BQ11: 0 | BT11: WOOD | BU11: dom | BV11: 0 | BX11: WOOD | BY11: 25.615143 | CA11: WOOD | CB11: 307.873 | CD11: WOOD | CE11: EMIRATI | CF11: 16.314918 | CH11: WOOD | CI11: 0 | CL11: WOOD | CM11: 0 | CP11: WOOD | CQ11: 0 | CT11: WOOD | CU11: AG | CV11: =OFFSET('Calculations 2'!$AJ$12,W11,X11) -> 0 | CY11: WOOD | CZ11: 0.5 | DC11: WOOD | DD11: 1.26 | DG11: WOOD | DH11: 2 | DK11: WOOD | DL11: 0.4 | DP11: WOOD | DQ11: 2 | DU11: WOOD | DV11: 2 | ED11: WOOD | EE11: 1 | EH11: WOOD | EI11: -3.6 | EQ11: WOOD
A12: PPP | C12: PPP | H12: PPP | I12: 7097.443 | J12: 7432.5429 | K12: 14529.986 | M12: =I12/$K12 -> 0.48846868 | N12: =J12/$K12 -> 0.51153132 | Q12: PPP | R12: dom | S12: AG | T12: =OFFSET('Calculations 2'!$C$45,W12,X12)*OFFSET($M$6,W12,0) -> 0 | V12: =V11+1 -> 6 | W12: =MOD(V12,$V$3) -> 6 | X12: =FLOOR(V12/$V$3,1) -> 0 | Z12: PPP | AA12: 0.0035752525 | AC12: PPP | AD12: dom | AE12: AG | AF12: =OFFSET('Calculations 2'!$CE$45,W12,0)*OFFSET($AA$6,X12,0)*OFFSET($M$6,W12,) -> 0.5109592 | AI12: PPP | AJ12: dom | AK12: =SUM('Calculations 2'!BY51:CB51)*M12 -> 125.19658 | AN12: PPP | AO12: 3806.5156 | AQ12: PPP | AR12: dom | AS12: 0 | AU12: PPP | AV12: 0 | AY12: PPP | AZ12: dom | BA12: AG | BB12: 0 | BE12: PPP | BF12: dom | BG12: AG | BH12: 0 | BK12: PPP | BL12: dom | BM12: 0 | BP12: PPP | BQ12: 0 | BT12: PPP | BU12: dom | BV12: 0 | BX12: PPP | BY12: 76.334952 | CA12: PPP | CB12: 879.574 | CD12: PPP | CE12: EMIRATI | CF12: 33.470438 | CH12: PPP | CI12: 0 | CL12: PPP | CM12: 0 | CP12: PPP | CQ12: 0 | CT12: PPP | CU12: AG | CV12: =OFFSET('Calculations 2'!$AJ$12,W12,X12) -> 0 | CY12: PPP | CZ12: 0.5 | DC12: PPP | DD12: 1.26 | DG12: PPP | DH12: 2 | DK12: PPP | DL12: 0.4 | DP12: PPP | DQ12: 2 | DU12: PPP | DV12: 2 | ED12: PPP | EE12: 1 | EH12: PPP | EI12: -3.6 | EQ12: PPP
A13: PC | C13: PC | H13: PC | I13: 28389.412 | J13: 49129.005 | K13: 77518.417 | M13: =I13/$K13 -> 0.36622797 | N13: =J13/$K13 -> 0.63377203 | Q13: PC | R13: dom | S13: AG | T13: =OFFSET('Calculations 2'!$C$45,W13,X13)*OFFSET($M$6,W13,0) -> 13.401128 | V13: =V12+1 -> 7 | W13: =MOD(V13,$V$3) -> 7 | X13: =FLOOR(V13/$V$3,1) -> 0 | Z13: PC | AA13: 0.0078380136 | AC13: PC | AD13: dom | AE13: AG | AF13: =OFFSET('Calculations 2'!$CE$45,W13,0)*OFFSET($AA$6,X13,0)*OFFSET($M$6,W13,) -> 0.077860293 | AI13: PC | AJ13: dom | AK13: =SUM('Calculations 2'!BY52:CB52)*M13 -> 661.44051 | AN13: PC | AO13: 23605.032 | AQ13: PC | AR13: dom | AS13: 0 | AU13: PC | AV13: 0 | AY13: PC | AZ13: dom | BA13: AG | BB13: 0 | BE13: PC | BF13: dom | BG13: AG | BH13: 0 | BK13: PC | BL13: dom | BM13: 0 | BP13: PC | BQ13: 0 | BT13: PC | BU13: dom | BV13: 0 | BX13: PC | BY13: 110.92151 | CA13: PC | CB13: 1928.287 | CD13: PC | CE13: EMIRATI | CF13: 6.6922626 | CH13: PC | CI13: 0 | CL13: PC | CM13: 0 | CP13: PC | CQ13: 0 | CT13: PC | CU13: AG | CV13: =OFFSET('Calculations 2'!$AJ$12,W13,X13) -> 0 | CY13: PC | CZ13: 0.5 | DC13: PC | DD13: 1.26 | DG13: PC | DH13: 2 | DK13: PC | DL13: 0.4 | DP13: PC | DQ13: 2 | DU13: PC | DV13: 2 | ED13: PC | EE13: 1 | EH13: PC | EI13: -3.6 | EQ13: PC
A14: CHM | C14: CHM | H14: CHM | I14: 13147.266 | J14: 50085.109 | K14: 63232.375 | M14: =I14/$K14 -> 0.20791985 | N14: =J14/$K14 -> 0.79208015 | Q14: CHM | R14: dom | S14: AG | T14: =OFFSET('Calculations 2'!$C$45,W14,X14)*OFFSET($M$6,W14,0) -> 1.3170773 | V14: =V13+1 -> 8 | W14: =MOD(V14,$V$3) -> 8 | X14: =FLOOR(V14/$V$3,1) -> 0 | Z14: CHM | AA14: 0.00990686 | AC14: CHM | AD14: dom | AE14: AG | AF14: =OFFSET('Calculations 2'!$CE$45,W14,0)*OFFSET($AA$6,X14,0)*OFFSET($M$6,W14,) -> 0.48485196 | AI14: CHM | AJ14: dom | AK14: =SUM('Calculations 2'!BY53:CB53)*M14 -> 527.86509 | AN14: CHM | AO14: 44799.938 | AQ14: CHM | AR14: dom | AS14: 0 | AU14: CHM | AV14: 0 | AY14: CHM | AZ14: dom | BA14: AG | BB14: 0 | BE14: CHM | BF14: dom | BG14: AG | BH14: 0 | BK14: CHM | BL14: dom | BM14: 0 | BP14: CHM | BQ14: 0 | BT14: CHM | BU14: dom | BV14: 0 | BX14: CHM | BY14: 341.30384 | CA14: CHM | CB14: 2437.259 | CD14: CHM | CE14: EMIRATI | CF14: 40.239678 | CH14: CHM | CI14: 0 | CL14: CHM | CM14: 0 | CP14: CHM | CQ14: 0 | CT14: CHM | CU14: AG | CV14: =OFFSET('Calculations 2'!$AJ$12,W14,X14) -> 0 | CY14: CHM | CZ14: 0.5 | DC14: CHM | DD14: 1.26 | DG14: CHM | DH14: 2 | DK14: CHM | DL14: 0.4 | DP14: CHM | DQ14: 2 | DU14: CHM | DV14: 2 | ED14: CHM | EE14: 1 | EH14: CHM | EI14: -3.6 | EQ14: CHM
A15: RUBBER | C15: RUBBER | H15: RUBBER | I15: 6406.529 | J15: 11940.515 | K15: 18347.044 | M15: =I15/$K15 -> 0.3491859 | N15: =J15/$K15 -> 0.6508141 | Q15: RUBBER | R15: dom | S15: AG | T15: =OFFSET('Calculations 2'!$C$45,W15,X15)*OFFSET($M$6,W15,0) -> 0 | V15: =V14+1 -> 9 | W15: =MOD(V15,$V$3) -> 9 | X15: =FLOOR(V15/$V$3,1) -> 0 | Z15: RUBBER | AA15: 0.0048881317 | AC15: RUBBER | AD15: dom | AE15: AG | AF15: =OFFSET('Calculations 2'!$CE$45,W15,0)*OFFSET($AA$6,X15,0)*OFFSET($M$6,W15,) -> 0.75898898 | AI15: RUBBER | AJ15: dom | AK15: =SUM('Calculations 2'!BY54:CB54)*M15 -> 2.6051403 | AN15: RUBBER | AO15: 11455.931 | AQ15: RUBBER | AR15: dom | AS15: 0 | AU15: RUBBER | AV15: 0 | AY15: RUBBER | AZ15: dom | BA15: AG | BB15: 0 | BE15: RUBBER | BF15: dom | BG15: AG | BH15: 0 | BK15: RUBBER | BL15: dom | BM15: 0 | BP15: RUBBER | BQ15: 0 | BT15: RUBBER | BU15: dom | BV15: 0 | BX15: RUBBER | BY15: 117.91219 | CA15: RUBBER | CB15: 1202.565 | CD15: RUBBER | CE15: EMIRATI | CF15: 18.177604 | CH15: RUBBER | CI15: 0 | CL15: RUBBER | CM15: 0 | CP15: RUBBER | CQ15: 0 | CT15: RUBBER | CU15: AG | CV15: =OFFSET('Calculations 2'!$AJ$12,W15,X15) -> 0 | CY15: RUBBER | CZ15: 0.5 | DC15: RUBBER | DD15: 1.26 | DG15: RUBBER | DH15: 2 | DK15: RUBBER | DL15: 0.4 | DP15: RUBBER | DQ15: 2 | DU15: RUBBER | DV15: 2 | ED15: RUBBER | EE15: 1 | EH15: RUBBER | EI15: -3.6 | EQ15: RUBBER
A16: NMM | C16: NMM | H16: NMM | I16: 8147.143 | J16: 6187.5803 | K16: 14334.723 | M16: =I16/$K16 -> 0.56835021 | N16: =J16/$K16 -> 0.43164979 | Q16: NMM | R16: dom | S16: AG | T16: =OFFSET('Calculations 2'!$C$45,W16,X16)*OFFSET($M$6,W16,0) -> 0 | V16: =V15+1 -> 10 | W16: =MOD(V16,$V$3) -> 10 | X16: =FLOOR(V16/$V$3,1) -> 0 | Z16: NMM | AA16: 0.0034431521 | AC16: NMM | AD16: dom | AE16: AG | AF16: =OFFSET('Calculations 2'!$CE$45,W16,0)*OFFSET($AA$6,X16,0)*OFFSET($M$6,W16,) -> 0.70310895 | AI16: NMM | AJ16: dom | AK16: =SUM('Calculations 2'!BY55:CB55)*M16 -> 50.778097 | AN16: NMM | AO16: 4728.6533 | AQ16: NMM | AR16: dom | AS16: 0 | AU16: NMM | AV16: 0 | AY16: NMM | AZ16: dom | BA16: AG | BB16: 0 | BE16: NMM | BF16: dom | BG16: AG | BH16: 0 | BK16: NMM | BL16: dom | BM16: 0 | BP16: NMM | BQ16: 0 | BT16: NMM | BU16: dom | BV16: 0 | BX16: NMM | BY16: 78.717072 | CA16: NMM | CB16: 847.075 | CD16: NMM | CE16: EMIRATI | CF16: 44.044585 | CH16: NMM | CI16: 0 | CL16: NMM | CM16: 0 | CP16: NMM | CQ16: 0 | CT16: NMM | CU16: AG | CV16: =OFFSET('Calculations 2'!$AJ$12,W16,X16) -> 0 | CY16: NMM | CZ16: 0.5 | DC16: NMM | DD16: 1.26 | DG16: NMM | DH16: 2 | DK16: NMM | DL16: 0.4 | DP16: NMM | DQ16: 2 | DU16: NMM | DV16: 2 | ED16: NMM | EE16: 1 | EH16: NMM | EI16: -3.6 | EQ16: NMM
A17: METAL | C17: METAL | H17: METAL | I17: 38703.505 | J17: 125797.11 | K17: 164500.62 | M17: =I17/$K17 -> 0.23527878 | N17: =J17/$K17 -> 0.76472122 | Q17: METAL | R17: dom | S17: AG | T17: =OFFSET('Calculations 2'!$C$45,W17,X17)*OFFSET($M$6,W17,0) -> 0 | V17: =V16+1 -> 11 | W17: =MOD(V17,$V$3) -> 11 | X17: =FLOOR(V17/$V$3,1) -> 0 | Z17: METAL | AA17: 0.029767971 | AC17: METAL | AD17: dom | AE17: AG | AF17: =OFFSET('Calculations 2'!$CE$45,W17,0)*OFFSET($AA$6,X17,0)*OFFSET($M$6,W17,) -> 2.0564721 | AI17: METAL | AJ17: dom | AK17: =SUM('Calculations 2'!BY56:CB56)*M17 -> 22.327324 | AN17: METAL | AO17: 129405.85 | AQ17: METAL | AR17: dom | AS17: 0 | AU17: METAL | AV17: 0 | AY17: METAL | AZ17: dom | BA17: AG | BB17: 0 | BE17: METAL | BF17: dom | BG17: AG | BH17: 0 | BK17: METAL | BL17: dom | BM17: 0 | BP17: METAL | BQ17: 0 | BT17: METAL | BU17: dom | BV17: 0 | BX17: METAL | BY17: 767.68665 | CA17: METAL | CB17: 7323.436 | CD17: METAL | CE17: EMIRATI | CF17: 104.69835 | CH17: METAL | CI17: 0 | CL17: METAL | CM17: 0 | CP17: METAL | CQ17: 0 | CT17: METAL | CU17: AG | CV17: =OFFSET('Calculations 2'!$AJ$12,W17,X17) -> 0 | CY17: METAL | CZ17: 0.5 | DC17: METAL | DD17: 1.26 | DG17: METAL | DH17: 2 | DK17: METAL | DL17: 0.4 | DP17: METAL | DQ17: 2 | DU17: METAL | DV17: 2 | ED17: METAL | EE17: 1 | EH17: METAL | EI17: -3.6 | EQ17: METAL
A18: MACH | C18: MACH | H18: MACH | I18: 7111.347 | J18: 61173.541 | K18: 68284.888 | M18: =I18/$K18 -> 0.10414232 | N18: =J18/$K18 -> 0.89585768 | Q18: MACH | R18: dom | S18: AG | T18: =OFFSET('Calculations 2'!$C$45,W18,X18)*OFFSET($M$6,W18,0) -> 0 | V18: =V17+1 -> 12 | W18: =MOD(V18,$V$3) -> 12 | X18: =FLOOR(V18/$V$3,1) -> 0 | Z18: MACH | AA18: 0.0039926053 | AC18: MACH | AD18: dom | AE18: AG | AF18: =OFFSET('Calculations 2'!$CE$45,W18,0)*OFFSET($AA$6,X18,0)*OFFSET($M$6,W18,) -> 2.9765813 | AI18: MACH | AJ18: dom | AK18: =SUM('Calculations 2'!BY57:CB57)*M18 -> 2.4711649 | AN18: MACH | AO18: 40306.888 | AQ18: MACH | AR18: dom | AS18: 0 | AU18: MACH | AV18: 0 | AY18: MACH | AZ18: dom | BA18: AG | BB18: 0 | BE18: MACH | BF18: dom | BG18: AG | BH18: 0 | BK18: MACH | BL18: dom | BM18: 0 | BP18: MACH | BQ18: 0 | BT18: MACH | BU18: dom | BV18: 0 | BX18: MACH | BY18: 552.83399 | CA18: MACH | CB18: 982.25 | CD18: MACH | CE18: EMIRATI | CF18: 34.173652 | CH18: MACH | CI18: 0 | CL18: MACH | CM18: 0 | CP18: MACH | CQ18: 0 | CT18: MACH | CU18: AG | CV18: =OFFSET('Calculations 2'!$AJ$12,W18,X18) -> 0 | CY18: MACH | CZ18: 0.5 | DC18: MACH | DD18: 1.26 | DG18: MACH | DH18: 2 | DK18: MACH | DL18: 0.4 | DP18: MACH | DQ18: 2 | DU18: MACH | DV18: 2 | ED18: MACH | EE18: 1 | EH18: MACH | EI18: -3.6 | EQ18: MACH
A19: ELEC | C19: ELEC | H19: ELEC | I19: 6245.682 | J19: 138479.37 | K19: 144725.05 | M19: =I19/$K19 -> 0.043155499 | N19: =J19/$K19 -> 0.9568445 | Q19: ELEC | R19: dom | S19: AG | T19: =OFFSET('Calculations 2'!$C$45,W19,X19)*OFFSET($M$6,W19,0) -> 0 | V19: =V18+1 -> 13 | W19: =MOD(V19,$V$3) -> 13 | X19: =FLOOR(V19/$V$3,1) -> 0 | Z19: ELEC | AA19: 0.0027857674 | AC19: ELEC | AD19: dom | AE19: AG | AF19: =OFFSET('Calculations 2'!$CE$45,W19,0)*OFFSET($AA$6,X19,0)*OFFSET($M$6,W19,) -> 0.61919349 | AI19: ELEC | AJ19: dom | AK19: =SUM('Calculations 2'!BY58:CB58)*M19 -> 15.927874 | AN19: ELEC | AO19: 127465.51 | AQ19: ELEC | AR19: dom | AS19: 0 | AU19: ELEC | AV19: 0 | AY19: ELEC | AZ19: dom | BA19: AG | BB19: 0 | BE19: ELEC | BF19: dom | BG19: AG | BH19: 0 | BK19: ELEC | BL19: dom | BM19: 0 | BP19: ELEC | BQ19: 0 | BT19: ELEC | BU19: dom | BV19: 0 | BX19: ELEC | BY19: 901.72973 | CA19: ELEC | CB19: 685.347 | CD19: ELEC | CE19: EMIRATI | CF19: 19.647828 | CH19: ELEC | CI19: 0 | CL19: ELEC | CM19: 0 | CP19: ELEC | CQ19: 0 | CT19: ELEC | CU19: AG | CV19: =OFFSET('Calculations 2'!$AJ$12,W19,X19) -> 0 | CY19: ELEC | CZ19: 0.5 | DC19: ELEC | DD19: 1.26 | DG19: ELEC | DH19: 2 | DK19: ELEC | DL19: 0.4 | DP19: ELEC | DQ19: 2 | DU19: ELEC | DV19: 2 | ED19: ELEC | EE19: 1 | EH19: ELEC | EI19: -3.6 | EQ19: ELEC
A20: TRNEQUIP | C20: TRNEQUIP | H20: TRNEQUIP | I20: 2014.772 | J20: 49352.989 | K20: 51367.761 | M20: =I20/$K20 -> 0.0392225 | N20: =J20/$K20 -> 0.9607775 | Q20: TRNEQUIP | R20: dom | S20: AG | T20: =OFFSET('Calculations 2'!$C$45,W20,X20)*OFFSET($M$6,W20,0) -> 0 | V20: =V19+1 -> 14 | W20: =MOD(V20,$V$3) -> 14 | X20: =FLOOR(V20/$V$3,1) -> 0 | Z20: TRNEQUIP | AA20: 0.0024970438 | AC20: TRNEQUIP | AD20: dom | AE20: AG | AF20: =OFFSET('Calculations 2'!$CE$45,W20,0)*OFFSET($AA$6,X20,0)*OFFSET($M$6,W20,) -> 0.89442993 | AI20: TRNEQUIP | AJ20: dom | AK20: =SUM('Calculations 2'!BY59:CB59)*M20 -> 21.395993 | AN20: TRNEQUIP | AO20: 32111.616 | AQ20: TRNEQUIP | AR20: dom | AS20: 0 | AU20: TRNEQUIP | AV20: 0 | AY20: TRNEQUIP | AZ20: dom | BA20: AG | BB20: 0 | BE20: TRNEQUIP | BF20: dom | BG20: AG | BH20: 0 | BK20: TRNEQUIP | BL20: dom | BM20: 0 | BP20: TRNEQUIP | BQ20: 0 | BT20: TRNEQUIP | BU20: dom | BV20: 0 | BX20: TRNEQUIP | BY20: 798.31085 | CA20: TRNEQUIP | CB20: 614.316 | CD20: TRNEQUIP | CE20: EMIRATI | CF20: 7.7914024 | CH20: TRNEQUIP | CI20: 0 | CL20: TRNEQUIP | CM20: 0 | CP20: TRNEQUIP | CQ20: 0 | CT20: TRNEQUIP | CU20: AG | CV20: =OFFSET('Calculations 2'!$AJ$12,W20,X20) -> 0 | CY20: TRNEQUIP | CZ20: 0.5 | DC20: TRNEQUIP | DD20: 1.26 | DG20: TRNEQUIP | DH20: 2 | DK20: TRNEQUIP | DL20: 0.4 | DP20: TRNEQUIP | DQ20: 2 | DU20: TRNEQUIP | DV20: 2 | ED20: TRNEQUIP | EE20: 1 | EH20: TRNEQUIP | EI20: -3.6 | EQ20: TRNEQUIP
A21: ROMAN | C21: ROMAN | H21: ROMAN | I21: 13743.5 | J21: 46912.072 | K21: 60655.572 | M21: =I21/$K21 -> 0.22658265 | N21: =J21/$K21 -> 0.77341735 | Q21: ROMAN | R21: dom | S21: AG | T21: =OFFSET('Calculations 2'!$C$45,W21,X21)*OFFSET($M$6,W21,0) -> 0 | V21: =V20+1 -> 15 | W21: =MOD(V21,$V$3) -> 15 | X21: =FLOOR(V21/$V$3,1) -> 0 | Z21: ROMAN | AA21: 0.0081449839 | AC21: ROMAN | AD21: dom | AE21: AG | AF21: =OFFSET('Calculations 2'!$CE$45,W21,0)*OFFSET($AA$6,X21,0)*OFFSET($M$6,W21,) -> 2.4354747 | AI21: ROMAN | AJ21: dom | AK21: =SUM('Calculations 2'!BY60:CB60)*M21 -> 93.284318 | AN21: ROMAN | AO21: 45765.019 | AQ21: ROMAN | AR21: dom | AS21: 0 | AU21: ROMAN | AV21: 0 | AY21: ROMAN | AZ21: dom | BA21: AG | BB21: 0 | BE21: ROMAN | BF21: dom | BG21: AG | BH21: 0 | BK21: ROMAN | BL21: dom | BM21: 0 | BP21: ROMAN | BQ21: 0 | BT21: ROMAN | BU21: dom | BV21: 0 | BX21: ROMAN | BY21: 364.30454 | CA21: ROMAN | CB21: 2003.807 | CD21: ROMAN | CE21: EMIRATI | CF21: 74.587809 | CH21: ROMAN | CI21: 0 | CL21: ROMAN | CM21: 0 | CP21: ROMAN | CQ21: 0 | CT21: ROMAN | CU21: AG | CV21: =OFFSET('Calculations 2'!$AJ$12,W21,X21) -> 0 | CY21: ROMAN | CZ21: 0.5 | DC21: ROMAN | DD21: 1.26 | DG21: ROMAN | DH21: 2 | DK21: ROMAN | DL21: 0.4 | DP21: ROMAN | DQ21: 2 | DU21: ROMAN | DV21: 2 | ED21: ROMAN | EE21: 1 | EH21: ROMAN | EI21: -3.6 | EQ21: ROMAN
... A38: DWE | C38: DWE | H38: DWE | I38: 1945.3419 | J38: 0 | K38: 1945.3419 | M38: =I38/$K38 -> 1 | N38: =J38/$K38 -> 0 | Q38: DWE | R38: dom | S38: AG | T38: =OFFSET('Calculations 2'!$C$45,W38,X38)*OFFSET($M$6,W38,0) -> 0 | V38: =V37+1 -> 32 | W38: =MOD(V38,$V$3) -> 32 | X38: =FLOOR(V38/$V$3,1) -> 0 | Z38: DWE | AA38: 1.3898347e-06 | AC38: DWE | AD38: dom | AE38: AG | AF38: =OFFSET('Calculations 2'!$CE$45,W38,0)*OFFSET($AA$6,X38,0)*OFFSET($M$6,W38,) -> 0 | AI38: DWE | AJ38: dom | AK38: =SUM('Calculations 2'!BY77:CB77)*M38 -> 1945.3419 | AN38: DWE | AO38: 0 | AQ38: DWE | AR38: dom | AS38: 0 | AU38: DWE | AV38: 0 | AY38: DWE | AZ38: dom | BA38: AG | BB38: 0 | BE38: DWE | BF38: dom | BG38: AG | BH38: 0 | BK38: DWE | BL38: dom | BM38: 0 | BP38: DWE | BQ38: 0 | BT38: DWE | BU38: dom | BV38: 0 | BX38: DWE | BY38: 0 | CA38: DWE | CB38: 0.34192339 | CD38: DWE | CE38: EMIRATI | CF38: 147.79424 | CH38: DWE | CI38: 0 | CL38: DWE | CM38: 0 | CP38: DWE | CQ38: 0 | CT38: DWE | CU38: AG | CV38: =OFFSET('Calculations 2'!$AJ$12,W38,X38) -> 0 | CY38: DWE | CZ38: 0.5 | DC38: DWE | DD38: 1.26 | DG38: DWE | DH38: 2 | DK38: DWE | DL38: 0.4 | DP38: DWE | DQ38: 2 | DU38: DWE | DV38: 2 | ED38: DWE | EE38: 1 | EH38: DWE | EI38: -4 | EQ38: DWE
Q39: AG | R39: dom | S39: MIN | T39: =OFFSET('Calculations 2'!$C$45,W39,X39)*OFFSET($M$6,W39,0) -> 0 | V39: =V38+1 -> 33 | W39: =MOD(V39,$V$3) -> 0 | X39: =FLOOR(V39/$V$3,1) -> 1 | AC39: AG | AD39: dom | AE39: MIN | AF39: =OFFSET('Calculations 2'!$CE$45,W39,0)*OFFSET($AA$6,X39,0)*OFFSET($M$6,W39,) -> 0.66586338 | AI39: AG | AJ39: imp | AK39: =SUM('Calculations 2'!BY45:CB45)*N6 -> 2536.3645 | AQ39: AG | AR39: imp | AS39: {='Calculations 2'!CC45:CC77*N6:N38} -> 0 | AY39: AG | AZ39: dom | BA39: MIN | BB39: 0 | BE39: AG | BF39: dom | BG39: MIN | BH39: 0 | BK39: AG | BL39: imp | BM39: 0 | BT39: AG | BU39: imp | BV39: 0 | CD39: AG | CE39: MIGRANTHH | CF39: {=TRANSPOSE('Calculations 2'!C79:AI79)} -> 23.695215 | CT39: AG | CU39: MIN | CV39: =OFFSET('Calculations 2'!$AJ$12,W39,X39) -> 0
Q40: MIN | R40: dom | S40: MIN | T40: =OFFSET('Calculations 2'!$C$45,W40,X40)*OFFSET($M$6,W40,0) -> 49.580861 | V40: =V39+1 -> 34 | W40: =MOD(V40,$V$3) -> 1 | X40: =FLOOR(V40/$V$3,1) -> 1 | AC40: MIN | AD40: dom | AE40: MIN | AF40: =OFFSET('Calculations 2'!$CE$45,W40,0)*OFFSET($AA$6,X40,0)*OFFSET($M$6,W40,) -> 1.1615442 | AI40: MIN | AJ40: imp | AK40: =SUM('Calculations 2'!BY46:CB46)*N7 -> 475.05536 | AQ40: MIN | AR40: imp | AS40: 0 | AY40: MIN | AZ40: dom | BA40: MIN | BB40: 0 | BE40: MIN | BF40: dom | BG40: MIN | BH40: 0 | BK40: MIN | BL40: imp | BM40: 0 | BT40: MIN | BU40: imp | BV40: 0 | CD40: MIN | CE40: MIGRANTHH | CF40: 650.11793 | CT40: MIN | CU40: MIN | CV40: =OFFSET('Calculations 2'!$AJ$12,W40,X40) -> 11448.729
Q41: FBT | R41: dom | S41: MIN | T41: =OFFSET('Calculations 2'!$C$45,W41,X41)*OFFSET($M$6,W41,0) -> 0 | V41: =V40+1 -> 35 | W41: =MOD(V41,$V$3) -> 2 | X41: =FLOOR(V41/$V$3,1) -> 1 | AC41: FBT | AD41: dom | AE41: MIN | AF41: =OFFSET('Calculations 2'!$CE$45,W41,0)*OFFSET($AA$6,X41,0)*OFFSET($M$6,W41,) -> 1.9557959 | AI41: FBT | AJ41: imp | AK41: =SUM('Calculations 2'!BY47:CB47)*N8 -> 5883.6418 | AQ41: FBT | AR41: imp | AS41: 0 | AY41: FBT | AZ41: dom | BA41: MIN | BB41: 0 | BE41: FBT | BF41: dom | BG41: MIN | BH41: 0 | BK41: FBT | BL41: imp | BM41: 0 | BT41: FBT | BU41: imp | BV41: 0 | CD41: FBT | CE41: MIGRANTHH | CF41: 861.60638 | CT41: FBT | CU41: MIN | CV41: =OFFSET('Calculations 2'!$AJ$12,W41,X41) -> 0
Q42: TEX | R42: dom | S42: MIN | T42: =OFFSET('Calculations 2'!$C$45,W42,X42)*OFFSET($M$6,W42,0) -> 0 | V42: =V41+1 -> 36 | W42: =MOD(V42,$V$3) -> 3 | X42: =FLOOR(V42/$V$3,1) -> 1 | AC42: TEX | AD42: dom | AE42: MIN | AF42: =OFFSET('Calculations 2'!$CE$45,W42,0)*OFFSET($AA$6,X42,0)*OFFSET($M$6,W42,) -> 10.187457 | AI42: TEX | AJ42: imp | AK42: =SUM('Calculations 2'!BY48:CB48)*N9 -> 2415.2055 | AQ42: TEX | AR42: imp | AS42: 0 | AY42: TEX | AZ42: dom | BA42: MIN | BB42: 0 | BE42: TEX | BF42: dom | BG42: MIN | BH42: 0 | BK42: TEX | BL42: imp | BM42: 0 | BT42: TEX | BU42: imp | BV42: 0 | CD42: TEX | CE42: MIGRANTHH | CF42: 269.76131 | CT42: TEX | CU42: MIN | CV42: =OFFSET('Calculations 2'!$AJ$12,W42,X42) -> 0
Q43: LEATHER | R43: dom | S43: MIN | T43: =OFFSET('Calculations 2'!$C$45,W43,X43)*OFFSET($M$6,W43,0) -> 0 | V43: =V42+1 -> 37 | W43: =MOD(V43,$V$3) -> 4 | X43: =FLOOR(V43/$V$3,1) -> 1 | AC43: LEATHER | AD43: dom | AE43: MIN | AF43: =OFFSET('Calculations 2'!$CE$45,W43,0)*OFFSET($AA$6,X43,0)*OFFSET($M$6,W43,) -> 0.072287382 | AI43: LEATHER | AJ43: imp | AK43: =SUM('Calculations 2'!BY49:CB49)*N10 -> 1952.5284 | AQ43: LEATHER | AR43: imp | AS43: 0 | AY43: LEATHER | AZ43: dom | BA43: MIN | BB43: 0 | BE43: LEATHER | BF43: dom | BG43: MIN | BH43: 0 | BK43: LEATHER | BL43: imp | BM43: 0 | BT43: LEATHER | BU43: imp | BV43: 0 | CD43: LEATHER | CE43: MIGRANTHH | CF43: 2.4052201 | CT43: LEATHER | CU43: MIN | CV43: =OFFSET('Calculations 2'!$AJ$12,W43,X43) -> 0
Q44: WOOD | R44: dom | S44: MIN | T44: =OFFSET('Calculations 2'!$C$45,W44,X44)*OFFSET($M$6,W44,0) -> 0 | V44: =V43+1 -> 38 | W44: =MOD(V44,$V$3) -> 5 | X44: =FLOOR(V44/$V$3,1) -> 1 | AC44: WOOD | AD44: dom | AE44: MIN | AF44: =OFFSET('Calculations 2'!$CE$45,W44,0)*OFFSET($AA$6,X44,0)*OFFSET($M$6,W44,) -> 0.4450002 | AI44: WOOD | AJ44: imp | AK44: =SUM('Calculations 2'!BY50:CB50)*N11 -> 0 | AQ44: WOOD | AR44: imp | AS44: 0 | AY44: WOOD | AZ44: dom | BA44: MIN | BB44: 0 | BE44: WOOD | BF44: dom | BG44: MIN | BH44: 0 | BK44: WOOD | BL44: imp | BM44: 0 | BT44: WOOD | BU44: imp | BV44: 0 | CD44: WOOD | CE44: MIGRANTHH | CF44: 203.19907 | CT44: WOOD | CU44: MIN | CV44: =OFFSET('Calculations 2'!$AJ$12,W44,X44) -> 0
Q45: PPP | R45: dom | S45: MIN | T45: =OFFSET('Calculations 2'!$C$45,W45,X45)*OFFSET($M$6,W45,0) -> 0 | V45: =V44+1 -> 39 | W45: =MOD(V45,$V$3) -> 6 | X45: =FLOOR(V45/$V$3,1) -> 1 | AC45: PPP | AD45: dom | AE45: MIN | AF45: =OFFSET('Calculations 2'!$CE$45,W45,0)*OFFSET($AA$6,X45,0)*OFFSET($M$6,W45,) -> 8.9069554 | AI45: PPP | AJ45: imp | AK45: =SUM('Calculations 2'!BY51:CB51)*N12 -> 131.10763 | AQ45: PPP | AR45: imp | AS45: 0 | AY45: PPP | AZ45: dom | BA45: MIN | BB45: 0 | BE45: PPP | BF45: dom | BG45: MIN | BH45: 0 | BK45: PPP | BL45: imp | BM45: 0 | BT45: PPP | BU45: imp | BV45: 0 | CD45: PPP | CE45: MIGRANTHH | CF45: 416.86765 | CT45: PPP | CU45: MIN | CV45: =OFFSET('Calculations 2'!$AJ$12,W45,X45) -> 0
Q46: PC | R46: dom | S46: MIN | T46: =OFFSET('Calculations 2'!$C$45,W46,X46)*OFFSET($M$6,W46,0) -> 181.03496 | V46: =V45+1 -> 40 | W46: =MOD(V46,$V$3) -> 7 | X46: =FLOOR(V46/$V$3,1) -> 1 | AC46: PC | AD46: dom | AE46: MIN | AF46: =OFFSET('Calculations 2'!$CE$45,W46,0)*OFFSET($AA$6,X46,0)*OFFSET($M$6,W46,) -> 1.3572476 | AI46: PC | AJ46: imp | AK46: =SUM('Calculations 2'!BY52:CB52)*N13 -> 1144.6491 | AQ46: PC | AR46: imp | AS46: 0 | AY46: PC | AZ46: dom | BA46: MIN | BB46: 0 | BE46: PC | BF46: dom | BG46: MIN | BH46: 0 | BK46: PC | BL46: imp | BM46: 0 | BT46: PC | BU46: imp | BV46: 0 | CD46: PC | CE46: MIGRANTHH | CF46: 83.350803 | CT46: PC | CU46: MIN | CV46: =OFFSET('Calculations 2'!$AJ$12,W46,X46) -> 0
Q47: CHM | R47: dom | S47: MIN | T47: =OFFSET('Calculations 2'!$C$45,W47,X47)*OFFSET($M$6,W47,0) -> 0 | V47: =V46+1 -> 41 | W47: =MOD(V47,$V$3) -> 8 | X47: =FLOOR(V47/$V$3,1) -> 1 | AC47: CHM | AD47: dom | AE47: MIN | AF47: =OFFSET('Calculations 2'!$CE$45,W47,0)*OFFSET($AA$6,X47,0)*OFFSET($M$6,W47,) -> 8.4518583 | AI47: CHM | AJ47: imp | AK47: =SUM('Calculations 2'!BY53:CB53)*N14 -> 2010.9261 | AQ47: CHM | AR47: imp | AS47: 0 | AY47: CHM | AZ47: dom | BA47: MIN | BB47: 0 | BE47: CHM | BF47: dom | BG47: MIN | BH47: 0 | BK47: CHM | BL47: imp | BM47: 0 | BT47: CHM | BU47: imp | BV47: 0 | CD47: CHM | CE47: MIGRANTHH | CF47: 501.17719 | CT47: CHM | CU47: MIN | CV47: =OFFSET('Calculations 2'!$AJ$12,W47,X47) -> 0
Q48: RUBBER | R48: dom | S48: MIN | T48: =OFFSET('Calculations 2'!$C$45,W48,X48)*OFFSET($M$6,W48,0) -> 0 | V48: =V47+1 -> 42 | W48: =MOD(V48,$V$3) -> 9 | X48: =FLOOR(V48/$V$3,1) -> 1 | AC48: RUBBER | AD48: dom | AE48: MIN | AF48: =OFFSET('Calculations 2'!$CE$45,W48,0)*OFFSET($AA$6,X48,0)*OFFSET($M$6,W48,) -> 13.230569 | AI48: RUBBER | AJ48: imp | AK48: =SUM('Calculations 2'!BY54:CB54)*N15 -> 4.8554712 | AQ48: RUBBER | AR48: imp | AS48: 0 | AY48: RUBBER | AZ48: dom | BA48: MIN | BB48: 0 | BE48: RUBBER | BF48: dom | BG48: MIN | BH48: 0 | BK48: RUBBER | BL48: imp | BM48: 0 | BT48: RUBBER | BU48: imp | BV48: 0 | CD48: RUBBER | CE48: MIGRANTHH | CF48: 226.39843 | CT48: RUBBER | CU48: MIN | CV48: =OFFSET('Calculations 2'!$AJ$12,W48,X48) -> 0
Q49: NMM | R49: dom | S49: MIN | T49: =OFFSET('Calculations 2'!$C$45,W49,X49)*OFFSET($M$6,W49,0) -> 0 | V49: =V48+1 -> 43 | W49: =MOD(V49,$V$3) -> 10 | X49: =FLOOR(V49/$V$3,1) -> 1 | AC49: NMM | AD49: dom | AE49: MIN | AF49: =OFFSET('Calculations 2'!$CE$45,W49,0)*OFFSET($AA$6,X49,0)*OFFSET($M$6,W49,) -> 12.256478 | AI49: NMM | AJ49: imp | AK49: =SUM('Calculations 2'!BY55:CB55)*N16 -> 38.564875 | AQ49: NMM | AR49: imp | AS49: 0 | AY49: NMM | AZ49: dom | BA49: MIN | BB49: 0 | BE49: NMM | BF49: dom | BG49: MIN | BH49: 0 | BK49: NMM | BL49: imp | BM49: 0 | BT49: NMM | BU49: imp | BV49: 0 | CD49: NMM | CE49: MIGRANTHH | CF49: 548.56656 | CT49: NMM | CU49: MIN | CV49: =OFFSET('Calculations 2'!$AJ$12,W49,X49) -> 0
Q50: METAL | R50: dom | S50: MIN | T50: =OFFSET('Calculations 2'!$C$45,W50,X50)*OFFSET($M$6,W50,0) -> 0 | V50: =V49+1 -> 44 | W50: =MOD(V50,$V$3) -> 11 | X50: =FLOOR(V50/$V$3,1) -> 1 | AC50: METAL | AD50: dom | AE50: MIN | AF50: =OFFSET('Calculations 2'!$CE$45,W50,0)*OFFSET($AA$6,X50,0)*OFFSET($M$6,W50,) -> 35.848079 | AI50: METAL | AJ50: imp | AK50: =SUM('Calculations 2'!BY56:CB56)*N17 -> 72.569987 | AQ50: METAL | AR50: imp | AS50: 0 | AY50: METAL | AZ50: dom | BA50: MIN | BB50: 0 | BE50: METAL | BF50: dom | BG50: MIN | BH50: 0 | BK50: METAL | BL50: imp | BM50: 0 | BT50: METAL | BU50: imp | BV50: 0 | CD50: METAL | CE50: MIGRANTHH | CF50: 1303.9972 | CT50: METAL | CU50: MIN | CV50: =OFFSET('Calculations 2'!$AJ$12,W50,X50) -> 0
Q51: MACH | R51: dom | S51: MIN | T51: =OFFSET('Calculations 2'!$C$45,W51,X51)*OFFSET($M$6,W51,0) -> 0 | V51: =V50+1 -> 45 | W51: =MOD(V51,$V$3) -> 12 | X51: =FLOOR(V51/$V$3,1) -> 1 | AC51: MACH | AD51: dom | AE51: MIN | AF51: =OFFSET('Calculations 2'!$CE$45,W51,0)*OFFSET($AA$6,X51,0)*OFFSET($M$6,W51,) -> 51.887268 | AI51: MACH | AJ51: imp | AK51: =SUM('Calculations 2'!BY57:CB57)*N18 -> 21.257563 | AQ51: MACH | AR51: imp | AS51: 0 | AY51: MACH | AZ51: dom | BA51: MIN | BB51: 0 | BE51: MACH | BF51: dom | BG51: MIN | BH51: 0 | BK51: MACH | BL51: imp | BM51: 0 | BT51: MACH | BU51: imp | BV51: 0 | CD51: MACH | CE51: MIGRANTHH | CF51: 425.62606 | CT51: MACH | CU51: MIN | CV51: =OFFSET('Calculations 2'!$AJ$12,W51,X51) -> 0
... Q71: DWE | R71: dom | S71: MIN | T71: =OFFSET('Calculations 2'!$C$45,W71,X71)*OFFSET($M$6,W71,0) -> 0 | V71: =V70+1 -> 65 | W71: =MOD(V71,$V$3) -> 32 | X71: =FLOOR(V71/$V$3,1) -> 1 | AC71: DWE | AD71: dom | AE71: MIN | AF71: =OFFSET('Calculations 2'!$CE$45,W71,0)*OFFSET($AA$6,X71,0)*OFFSET($M$6,W71,) -> 0 | AI71: DWE | AJ71: imp | AK71: =SUM('Calculations 2'!BY77:CB77)*N38 -> 0 | AQ71: DWE | AR71: imp | AS71: 0 | AY71: DWE | AZ71: dom | BA71: MIN | BB71: 0 | BE71: DWE | BF71: dom | BG71: MIN | BH71: 0 | BK71: DWE | BL71: imp | BM71: 0 | BT71: DWE | BU71: imp | BV71: 0 | CD71: DWE | CE71: MIGRANTHH | CF71: 1275.7365 | CT71: DWE | CU71: MIN | CV71: =OFFSET('Calculations 2'!$AJ$12,W71,X71) -> 0
Q72: AG | R72: dom | S72: FBT | T72: =OFFSET('Calculations 2'!$C$45,W72,X72)*OFFSET($M$6,W72,0) -> 203.88011 | V72: =V71+1 -> 66 | W72: =MOD(V72,$V$3) -> 0 | X72: =FLOOR(V72/$V$3,1) -> 2 | AC72: AG | AD72: dom | AE72: FBT | AF72: =OFFSET('Calculations 2'!$CE$45,W72,0)*OFFSET($AA$6,X72,0)*OFFSET($M$6,W72,) -> 0.31347556 | AY72: AG | AZ72: dom | BA72: FBT | BB72: 0 | BE72: AG | BF72: dom | BG72: FBT | BH72: 0 | CD72: AG | CE72: MIGRANTCOMB | CF72: {=TRANSPOSE('Calculations 2'!C80:AI80)} -> 132.08054 | CT72: AG | CU72: FBT | CV72: =OFFSET('Calculations 2'!$AJ$12,W72,X72) -> 0
Q73: MIN | R73: dom | S73: FBT | T73: =OFFSET('Calculations 2'!$C$45,W73,X73)*OFFSET($M$6,W73,0) -> 7.7002252 | V73: =V72+1 -> 67 | W73: =MOD(V73,$V$3) -> 1 | X73: =FLOOR(V73/$V$3,1) -> 2 | AC73: MIN | AD73: dom | AE73: FBT | AF73: =OFFSET('Calculations 2'!$CE$45,W73,0)*OFFSET($AA$6,X73,0)*OFFSET($M$6,W73,) -> 0.54683248 | AY73: MIN | AZ73: dom | BA73: FBT | BB73: 0 | BE73: MIN | BF73: dom | BG73: FBT | BH73: 0 | CD73: MIN | CE73: MIGRANTCOMB | CF73: 167.09936 | CT73: MIN | CU73: FBT | CV73: =OFFSET('Calculations 2'!$AJ$12,W73,X73) -> 0
Q74: FBT | R74: dom | S74: FBT | T74: =OFFSET('Calculations 2'!$C$45,W74,X74)*OFFSET($M$6,W74,0) -> 3134.5643 | V74: =V73+1 -> 68 | W74: =MOD(V74,$V$3) -> 2 | X74: =FLOOR(V74/$V$3,1) -> 2 | AC74: FBT | AD74: dom | AE74: FBT | AF74: =OFFSET('Calculations 2'!$CE$45,W74,0)*OFFSET($AA$6,X74,0)*OFFSET($M$6,W74,) -> 0.92075075 | AY74: FBT | AZ74: dom | BA74: FBT | BB74: 0 | BE74: FBT | BF74: dom | BG74: FBT | BH74: 0 | CD74: FBT | CE74: MIGRANTCOMB | CF74: 994.88488 | CT74: FBT | CU74: FBT | CV74: =OFFSET('Calculations 2'!$AJ$12,W74,X74) -> 25557.719
Q75: TEX | R75: dom | S75: FBT | T75: =OFFSET('Calculations 2'!$C$45,W75,X75)*OFFSET($M$6,W75,0) -> 5.2170992 | V75: =V74+1 -> 69 | W75: =MOD(V75,$V$3) -> 3 | X75: =FLOOR(V75/$V$3,1) -> 2 | AC75: TEX | AD75: dom | AE75: FBT | AF75: =OFFSET('Calculations 2'!$CE$45,W75,0)*OFFSET($AA$6,X75,0)*OFFSET($M$6,W75,) -> 4.7960573 | AY75: TEX | AZ75: dom | BA75: FBT | BB75: 0 | BE75: TEX | BF75: dom | BG75: FBT | BH75: 0 | CD75: TEX | CE75: MIGRANTCOMB | CF75: 311.48962 | CT75: TEX | CU75: FBT | CV75: =OFFSET('Calculations 2'!$AJ$12,W75,X75) -> 0
Q76: LEATHER | R76: dom | S76: FBT | T76: =OFFSET('Calculations 2'!$C$45,W76,X76)*OFFSET($M$6,W76,0) -> 0 | V76: =V75+1 -> 70 | W76: =MOD(V76,$V$3) -> 4 | X76: =FLOOR(V76/$V$3,1) -> 2 | AC76: LEATHER | AD76: dom | AE76: FBT | AF76: =OFFSET('Calculations 2'!$CE$45,W76,0)*OFFSET($AA$6,X76,0)*OFFSET($M$6,W76,) -> 0.034031497 | AY76: LEATHER | AZ76: dom | BA76: FBT | BB76: 0 | BE76: LEATHER | BF76: dom | BG76: FBT | BH76: 0 | CD76: LEATHER | CE76: MIGRANTCOMB | CF76: 2.7772738 | CT76: LEATHER | CU76: FBT | CV76: =OFFSET('Calculations 2'!$AJ$12,W76,X76) -> 0
Q77: WOOD | R77: dom | S77: FBT | T77: =OFFSET('Calculations 2'!$C$45,W77,X77)*OFFSET($M$6,W77,0) -> 0 | V77: =V76+1 -> 71 | W77: =MOD(V77,$V$3) -> 5 | X77: =FLOOR(V77/$V$3,1) -> 2 | AC77: WOOD | AD77: dom | AE77: FBT | AF77: =OFFSET('Calculations 2'!$CE$45,W77,0)*OFFSET($AA$6,X77,0)*OFFSET($M$6,W77,) -> 0.20949746 | AY77: WOOD | AZ77: dom | BA77: FBT | BB77: 0 | BE77: WOOD | BF77: dom | BG77: FBT | BH77: 0 | CD77: WOOD | CE77: MIGRANTCOMB | CF77: 234.63114 | CT77: WOOD | CU77: FBT | CV77: =OFFSET('Calculations 2'!$AJ$12,W77,X77) -> 0
...

Sheet MAP
D2: Activities | H2: Commodities | L2: Factors | P2: Tax | S2: Institutions | Z2: Capital
C3: Million AED | D3: Agriculture, hunting, forestry, and fishing | E3: Mining and quarrying | F3: Other community, social, and personal services | G3: Private households with employed persons | H3: Agriculture, hunting, forestry, and fishing | I3: Mining and quarrying | J3: Other community, social, and personal services | K3: Private households with employed persons | L3: Emirati Labour | M3: Migrant Labour | N3: Commuting Labour | O3: Capital | P3: Indirect taxes | Q3: Subsidies | R3: Direct taxes | S3: Emirati Household | T3: Non-Emirati Household | U3: Collective Households | V3: Labour Camps | W3: Commuting household | X3: Government | Y3: Rest of the World | Z3: Savings - Investment
B4: Activities | C4: Agriculture, hunting, forestry, and fishing | D4: 0 | E4: 0 | F4: 0 | G4: 0 | H4: 1512.2992 | I4: 0 | J4: MAKE | K4: 0 | L4: 0 | M4: 0 | N4: 0 | O4: 0 | P4: 0 | Q4: 0 | R4: 0 | S4: 0 | T4: 0 | U4: 0 | V4: 0 | W4: 0 | X4: 0 | Y4: 0 | Z4: 0
C5: Mining and quarrying | D5: 0 | E5: 0 | F5: 0 | G5: 0 | H5: 0 | I5: 11448.729 | J5: 0 | K5: 0 | L5: 0 | M5: 0 | N5: 0 | O5: 0 | P5: 0 | Q5: 0 | R5: 0 | S5: 0 | T5: 0 | U5: 0 | V5: 0 | W5: 0 | X5: 0 | Y5: 0 | Z5: 0
C6: Other community, social, and personal services | D6: 0 | E6: 0 | F6: 0 | G6: 0 | H6: 0 | I6: 0 | J6: 7820.8397 | K6: 0 | L6: 0 | M6: 0 | N6: 0 | O6: 0 | P6: 0 | Q6: 0 | R6: 0 | S6: 0 | T6: 0 | U6: 0 | V6: 0 | W6: 0 | X6: 0 | Y6: 0 | Z6: 0
C7: Private households with employed persons | D7: 0 | E7: 0 | F7: 0 | G7: 0 | H7: 0 | I7: 0 | J7: 0 | K7: 1945.3419 | L7: 0 | M7: 0 | N7: 0 | O7: 0 | P7: 0 | Q7: 0 | R7: 0 | S7: 0 | T7: 0 | U7: 0 | V7: 0 | W7: 0 | X7: 0 | Y7: 0 | Z7: 0
B8: Commodities | C8: Agriculture, hunting, forestry, and fishing | D8: 143.07824 | E8: 0 | F8: V1BAS | G8: 0 | H8: 0 | I8: 0 | J8: 0 | K8: 0 | L8: 0 | M8: 0 | N8: 0 | O8: 0 | P8: 0 | Q8: 0 | R8: 0 | S8: 650.05757 | T8: 1816.241 | U8: 181.61415 | V8: 76.877273 | W8: 0 | X8: 0 | Y8: 13478.352 | Z8: 327.99153
C9: Mining and quarrying | D9: 0 | E9: 653.16941 | F9: 0 | G9: 0 | H9: 0 | I9: 0 | J9: 0 | K9: 0 | L9: 0 | M9: 0 | N9: 0 | O9: 0 | P9: 0 | Q9: 0 | R9: 0 | S9: 72.153961 | T9: 3BAS | U9: 42.576965 | V9: 9.3433054 | W9: 0 | X9: 5BAS | Y9: 4BAS | Z9: 521.23281
C10: Other community, social, and personal services | D10: 0 | E10: 2.5079417 | F10: 101.93045 | G10: 0 | H10: 0 | I10: 0 | J10: 0 | K10: 0 | L10: 0 | M10: 0 | N10: 0 | O10: 0 | P10: 0 | Q10: 0 | R10: 0 | S10: 600.69964 | T10: 1250.5101 | U10: 33.165917 | V10: 3.978187 | W10: 0 | X10: 811.9882 | Y10: 3516.9782 | Z10: 2BAS
C11: Private households with employed persons | D11: 0 | E11: 0 | F11: 0 | G11: 0 | H11: 0 | I11: 0 | J11: 0 | K11: 0 | L11: 0 | M11: 0 | N11: 0 | O11: 0 | P11: 0 | Q11: 0 | R11: 0 | S11: 845.94664 | T11: 1026.5238 | U11: 47.701429 | V11: 25.170006 | W11: 0 | X11: 0 | Y11: 0 | Z11: 0
B12: Factors | C12: Emirati Labour | D12: 14.240861 | E12: 90.364734 | F12: V1LAB | G12: 147.79424 | H12: 0 | I12: 0 | J12: 0 | K12: 0 | L12: 0 | M12: 0 | N12: 0 | O12: 0 | P12: 0 | Q12: 0 | R12: 0 | S12: 0 | T12: 0 | U12: 0 | V12: 0 | W12: 0 | X12: 0 | Y12: 0 | Z12: 0
C13: Migrant Labour | D13: 155.77576 | E13: 817.21729 | F13: 1850.1452 | G13: 1279.7686 | H13: 0 | I13: 0 | J13: 0 | K13: 0 | L13: 0 | M13: 0 | N13: 0 | O13: 0 | P13: 0 | Q13: 0 | R13: 0 | S13: 0 | T13: 0 | U13: 0 | V13: 0 | W13: 0 | X13: 0 | Y13: 0 | Z13: 0
C14: Commuting Labour | D14: 62.983383 | E14: 330.41798 | F14: 748.05224 | G14: 517.43712 | H14: 0 | I14: 0 | J14: 0 | K14: 0 | L14: 0 | M14: 0 | N14: 0 | O14: 0 | P14: 0 | Q14: 0 | R14: 0 | S14: 0 | T14: 0 | U14: 0 | V14: 0 | W14: 0 | X14: 0 | Y14: 0 | Z14: 0
C15: Capital | D15: 414.32237 | E15: 7222.3983 | F15: V1CAP | G15: 0.34192339 | H15: 0 | I15: 0 | J15: 0 | K15: 0 | L15: 0 | M15: 0 | N15: 0 | O15: 0 | P15: 0 | Q15: 0 | R15: 0 | S15: 0 | T15: 0 | U15: 0 | V15: 0 | W15: 0 | X15: 0 | Y15: 0 | Z15: 0
B16: Tax | C16: Indirect taxes | D16: 0 | E16: 0 | F16: 0 | G16: 0 | H16: 144.4832 | I16: 0TAR | J16: 200.26044 | K16: 0 | L16: 0 | M16: 0 | N16: 0 | O16: 0 | P16: 0 | Q16: 0 | R16: 0 | S16: 0 | T16: 0 | U16: 0 | V16: 0 | W16: 0 | X16: 0 | Y16: 0 | Z16: 0
C17: Subsidies | D17: 0 | E17: 0 | F17: 0 | G17: 0 | H17: 0 | I17: 0 | J17: 0 | K17: 0 | L17: 0 | M17: 0 | N17: 0 | O17: 0 | P17: 0 | Q17: 0 | R17: 0 | S17: 0 | T17: 0 | U17: 0 | V17: 0 | W17: 0 | X17: 0 | Y17: 0 | Z17: 0
C18: Direct taxes | D18: 0 | E18: 0 | F18: 0 | G18: 0 | H18: 0 | I18: 0 | J18: 0 | K18: 0 | L18: 0 | M18: 0 | N18: 0 | O18: 39520 | P18: 0 | Q18: 0 | R18: 0 | S18: 0 | T18: 0 | U18: 0 | V18: 0 | W18: 0 | X18: 0 | Y18: 0 | Z18: 0
B19: Institutions | C19: Emirati Household | D19: 0 | E19: 0 | F19: 0 | G19: 0 | H19: 0 | I19: 0 | J19: 0 | K19: 0 | L19: 16934.765 | M19: 0 | N19: 0 | O19: 185847.58 | P19: 0 | Q19: 0 | R19: 0 | S19: 0 | T19: 0 | U19: 0 | V19: 0 | W19: 0 | X19: 20278.234 | Y19: 0 | Z19: 0
C20: Non-Emirati Household | D20: 0 | E20: 0 | F20: 0 | G20: 0 | H20: 0 | I20: 0 | J20: 0 | K20: 0 | L20: 0 | M20: 90773.272 | N20: 0 | O20: 20649.731 | P20: 0 | Q20: 0 | R20: 0 | S20: 0 | T20: 0 | U20: 0 | V20: 0 | W20: 0 | X20: 0 | Y20: 0 | Z20: 0
C21: Collective Households | D21: 0 | E21: 0 | F21: 0 | G21: 0 | H21: 0 | I21: 0 | J21: 0 | K21: 0 | L21: 0 | M21: 50235.39 | N21: 0 | O21: 0 | P21: 0 | Q21: 0 | R21: 0 | S21: 0 | T21: 0 | U21: 0 | V21: 0 | W21: 0 | X21: 0 | Y21: 0 | Z21: 0
C22: Labour Camps | D22: 0 | E22: 0 | F22: 0 | G22: 0 | H22: 0 | I22: 0 | J22: 0 | K22: 0 | L22: 0 | M22: 18952.739 | N22: 0 | O22: 0 | P22: 0 | Q22: 0 | R22: 0 | S22: 0 | T22: 0 | U22: 0 | V22: 0 | W22: 0 | X22: 0 | Y22: 0 | Z22: 0
C23: Commuting Household | D23: 0 | E23: 0 | F23: 0 | G23: 0 | H23: 0 | I23: 0 | J23: 0 | K23: 0 | L23: 0 | M23: 0 | N23: 64675.726 | O23: 0 | P23: 0 | Q23: 0 | R23: 0 | S23: 0 | T23: 0 | U23: 0 | V23: 0 | W23: 0 | X23: 0 | Y23: 0 | Z23: 0
C24: Government | D24: 0 | E24: 0 | F24: 0 | G24: 0 | H24: 0 | I24: 0 | J24: 0 | K24: 0 | L24: 0 | M24: 0 | N24: 0 | O24: 0 | P24: 18030 | Q24: 0 | R24: 39520 | S24: 3180.3749 | T24: 8363.7131 | U24: 942.81661 | V24: 1031.9181 | W24: 0 | X24: 0 | Y24: 0 | Z24: 0
C25: Rest of the World | D25: 0 | E25: 0 | F25: 0 | G25: 0 | H25: 20212.322 | I25: Feeds into the 'imp' of BAS | J25: 449.61518 | K25: 0 | L25: 0 | M25: 0 | N25: 0 | O25: 0 | P25: 0 | Q25: 0 | R25: 0 | S25: 113534.54 | T25: 26449.301 | U25: 42510.857 | V25: 13191.575 | W25: 64675.726 | X25: 0 | Y25: 0 | Z25: 0
B26: Capital | C26: Savings - Investment | D26: 0 | E26: 0 | F26: 0 | G26: 0 | H26: 0 | I26: 0 | J26: 0 | K26: 0 | L26: 0 | M26: 0 | N26: 0 | O26: 0 | P26: 0 | Q26: 0 | R26: 0 | S26: 69448.446 | T26: 7716.494 | U26: 0 | V26: 0 | W26: 0 | X26: 2800 | Y26: 36587.752 | Z26: 0
C30: V6BAS set to zero
C31: V2TAX set to zero for domestic

Sheet Calculations 2
A1: Transfer assumptions
A3: Government transfers to Emirati households | D3: -1.2836954e-16 | E3: of emirati non-transfer income | G3: =D3*Calculations!BX356 -> -2.6031075e-11
A4: Households transfers to government | D4: =2/3 -> 0.66666667 | E4: of government transfers - allocated proportiunally to real estate expenditure
A5: Emirati Household | D5: =G$3*D$4*Calculations!BX$334/SUM(Calculations!BX$334:CA$334) -> -4.0826326e-12 | F5: =D5 -> -4.0826326e-12
A6: Non-Emirati Household | D6: =G$3*D$4*Calculations!BY$334/SUM(Calculations!BX$334:CA$334) -> -1.073646e-11 | F6: =D6 -> -1.073646e-11
A7: Collective Households | D7: =G$3*D$4*Calculations!BZ$334/SUM(Calculations!BX$334:CA$334) -> -1.2102893e-12 | F7: =D7+D8 -> -2.5349578e-12
A8: Labour Camps | D8: =G$3*D$4*Calculations!CA$334/SUM(Calculations!BX$334:CA$334) -> -1.3246685e-12
C10: Activities | AJ10: Commodities | BQ10: Factors | BV10: Tax | BY10: Institutions | CE10: Capital
B11: Million AED | C11: Agriculture, hunting, forestry, and fishing | D11: Mining and quarrying | E11: Food, beverages, and tobacco | F11: Textiles and textile products | G11: Leather, leather products, and footwear | H11: Wood and products of wood and cork | I11: Pulp, paper, paper products, printing, and publishing | J11: Coke, refined petroleum, and nuclear fuel | K11: Chemicals and chemical products | L11: Rubber and plastics | M11: Other nonmetallic minerals | N11: Basic metals and fabricated metal | O11: Machinery, nec | P11: Electrical and optical equipment | Q11: Transport equipment | R11: Manufacturing, nec; recycling | S11: Electricity, gas, and water supply | T11: Construction | U11: Wholesale and Retail Trade; Repair of Motor Vehicles and Motorcycles | V11: Hotels and restaurants | W11: Inland transport | X11: Water transport | Y11: Air transport | Z11: Other supporting and auxiliary transport activities; activities of travel agencies | AA11: Post and telecommunications | AB11: Financial intermediation | AC11: Real estate activities | AD11: Renting of M&Eq and other business activities | AE11: Public administration and defense; compulsory social security | AF11: Education | AG11: Health and social work | AH11: Other community, social, and personal services | AI11: Private households with employed persons | AJ11: Agriculture, hunting, forestry, and fishing | AK11: Mining and quarrying | AL11: Food, beverages, and tobacco | AM11: Textiles and textile products | AN11: Leather, leather products, and footwear | AO11: Wood and products of wood and cork | AP11: Pulp, paper, paper products, printing, and publishing | AQ11: Coke, refined petroleum, and nuclear fuel | AR11: Chemicals and chemical products | AS11: Rubber and plastics | AT11: Other nonmetallic minerals | AU11: Basic metals and fabricated metal | AV11: Machinery, nec | AW11: Electrical and optical equipment | AX11: Transport equipment | AY11: Manufacturing, nec; recycling | AZ11: Electricity, gas, and water supply | BA11: Construction | BB11: Wholesale and Retail Trade; Repair of Motor Vehicles and Motorcycles | BC11: Hotels and restaurants | BD11: Inland transport | BE11: Water transport | BF11: Air transport | BG11: Other supporting and auxiliary transport activities; activities of travel agencies | BH11: Post and telecommunications | BI11: Financial intermediation | BJ11: Real estate activities | BK11: Renting of M&Eq and other business activities | BL11: Public administration and defense; compulsory social security | BM11: Education | BN11: Health and social work | BO11: Other community, social, and personal services | BP11: Private households with employed persons | BQ11: Emirati Labour | BR11: Migrant HH | BS11: Migrant Combines | BT11: Commuting Labour | BU11: Capital | BV11: Indirect taxes | BW11: Subsidies | BX11: Direct taxes | BY11: Emirati Household | BZ11: Non-Emirati Household | CA11: Combines | CB11: Commuting household | CC11: Government | CD11: Rest of the World | CE11: Savings - Investment | CF11: TOTAL
A12: Activities | B12: Agriculture, hunting, forestry, and fishing | C12: =Calculations!C275 -> 0 | D12: =Calculations!D275 -> 0 | E12: =Calculations!E275 -> 0 | F12: =Calculations!F275 -> 0 | G12: =Calculations!G275 -> 0 | H12: =Calculations!H275 -> 0 | I12: =Calculations!I275 -> 0 | J12: =Calculations!J275 -> 0 | ... BR12: =Calculations!BR275 -> 0 | BS12: 0 | BT12: =Calculations!BS275 -> 0 | BU12: =Calculations!BT275 -> 0 | BV12: =Calculations!BU275 -> 0 | BW12: =Calculations!BV275 -> 0 | BX12: =Calculations!BW275 -> 0 | BY12: =Calculations!BX275 -> 0 | BZ12: =Calculations!BY275 -> 0 | CA12: =Calculations!BZ275+Calculations!CA275 -> 0 | CB12: =Calculations!CB275 -> 0 | CC12: =Calculations!CC275 -> 0 | CD12: =Calculations!CD275 -> 0 | CE12: =Calculations!CE275 -> 0 | CF12: =SUM(C12:CE12) -> 1512.2992 | CH12: {=CF12:CF92-TRANSPOSE(C93:CE93)} -> 0
B13: Mining and quarrying | C13: =Calculations!C276 -> 0 | D13: =Calculations!D276 -> 0 | E13: =Calculations!E276 -> 0 | F13: =Calculations!F276 -> 0 | G13: =Calculations!G276 -> 0 | H13: =Calculations!H276 -> 0 | I13: =Calculations!I276 -> 0 | J13: =Calculations!J276 -> 0 | ... BR13: =Calculations!BR276 -> 0 | BS13: 0 | BT13: =Calculations!BS276 -> 0 | BU13: =Calculations!BT276 -> 0 | BV13: =Calculations!BU276 -> 0 | BW13: =Calculations!BV276 -> 0 | BX13: =Calculations!BW276 -> 0 | BY13: =Calculations!BX276 -> 0 | BZ13: =Calculations!BY276 -> 0 | CA13: =Calculations!BZ276+Calculations!CA276 -> 0 | CB13: =Calculations!CB276 -> 0 | CC13: =Calculations!CC276 -> 0 | CD13: =Calculations!CD276 -> 0 | CE13: =Calculations!CE276 -> 0 | CF13: =SUM(C13:CE13) -> 11448.729 | CH13: 0
B14: Food, beverages, and tobacco | C14: =Calculations!C277 -> 0 | D14: =Calculations!D277 -> 0 | E14: =Calculations!E277 -> 0 | F14: =Calculations!F277 -> 0 | G14: =Calculations!G277 -> 0 | H14: =Calculations!H277 -> 0 | I14: =Calculations!I277 -> 0 | J14: =Calculations!J277 -> 0 | ... BR14: =Calculations!BR277 -> 0 | BS14: 0 | BT14: =Calculations!BS277 -> 0 | BU14: =Calculations!BT277 -> 0 | BV14: =Calculations!BU277 -> 0 | BW14: =Calculations!BV277 -> 0 | BX14: =Calculations!BW277 -> 0 | BY14: =Calculations!BX277 -> 0 | BZ14: =Calculations!BY277 -> 0 | CA14: =Calculations!BZ277+Calculations!CA277 -> 0 | CB14: =Calculations!CB277 -> 0 | CC14: =Calculations!CC277 -> 0 | CD14: =Calculations!CD277 -> 0 | CE14: =Calculations!CE277 -> 0 | CF14: =SUM(C14:CE14) -> 25557.719 | CH14: 0
B15: Textiles and textile products | C15: =Calculations!C278 -> 0 | D15: =Calculations!D278 -> 0 | E15: =Calculations!E278 -> 0 | F15: =Calculations!F278 -> 0 | G15: =Calculations!G278 -> 0 | H15: =Calculations!H278 -> 0 | I15: =Calculations!I278 -> 0 | J15: =Calculations!J278 -> 0 | ... BR15: =Calculations!BR278 -> 0 | BS15: 0 | BT15: =Calculations!BS278 -> 0 | BU15: =Calculations!BT278 -> 0 | BV15: =Calculations!BU278 -> 0 | BW15: =Calculations!BV278 -> 0 | BX15: =Calculations!BW278 -> 0 | BY15: =Calculations!BX278 -> 0 | BZ15: =Calculations!BY278 -> 0 | CA15: =Calculations!BZ278+Calculations!CA278 -> 0 | CB15: =Calculations!CB278 -> 0 | CC15: =Calculations!CC278 -> 0 | CD15: =Calculations!CD278 -> 0 | CE15: =Calculations!CE278 -> 0 | CF15: =SUM(C15:CE15) -> 3421.037 | CH15: 0
B16: Leather, leather products, and footwear | C16: =Calculations!C279 -> 0 | D16: =Calculations!D279 -> 0 | E16: =Calculations!E279 -> 0 | F16: =Calculations!F279 -> 0 | G16: =Calculations!G279 -> 0 | H16: =Calculations!H279 -> 0 | I16: =Calculations!I279 -> 0 | J16: =Calculations!J279 -> 0 | ... BR16: =Calculations!BR279 -> 0 | BS16: 0 | BT16: =Calculations!BS279 -> 0 | BU16: =Calculations!BT279 -> 0 | BV16: =Calculations!BU279 -> 0 | BW16: =Calculations!BV279 -> 0 | BX16: =Calculations!BW279 -> 0 | BY16: =Calculations!BX279 -> 0 | BZ16: =Calculations!BY279 -> 0 | CA16: =Calculations!BZ279+Calculations!CA279 -> 0 | CB16: =Calculations!CB279 -> 0 | CC16: =Calculations!CC279 -> 0 | CD16: =Calculations!CD279 -> 0 | CE16: =Calculations!CE279 -> 0 | CF16: =SUM(C16:CE16) -> 29.598 | CH16: 0
B17: Wood and products of wood and cork | C17: =Calculations!C280 -> 0 | D17: =Calculations!D280 -> 0 | E17: =Calculations!E280 -> 0 | F17: =Calculations!F280 -> 0 | G17: =Calculations!G280 -> 0 | H17: =Calculations!H280 -> 0 | I17: =Calculations!I280 -> 0 | J17: =Calculations!J280 -> 0 | ... BR17: =Calculations!BR280 -> 0 | BS17: 0 | BT17: =Calculations!BS280 -> 0 | BU17: =Calculations!BT280 -> 0 | BV17: =Calculations!BU280 -> 0 | BW17: =Calculations!BV280 -> 0 | BX17: =Calculations!BW280 -> 0 | BY17: =Calculations!BX280 -> 0 | BZ17: =Calculations!BY280 -> 0 | CA17: =Calculations!BZ280+Calculations!CA280 -> 0 | CB17: =Calculations!CB280 -> 0 | CC17: =Calculations!CC280 -> 0 | CD17: =Calculations!CD280 -> 0 | CE17: =Calculations!CE280 -> 0 | CF17: =SUM(C17:CE17) -> 2673.883 | CH17: 0
B18: Pulp, paper, paper products, printing, and publishing | C18: =Calculations!C281 -> 0 | D18: =Calculations!D281 -> 0 | E18: =Calculations!E281 -> 0 | F18: =Calculations!F281 -> 0 | G18: =Calculations!G281 -> 0 | H18: =Calculations!H281 -> 0 | I18: =Calculations!I281 -> 0 | J18: =Calculations!J281 -> 0 | ... BR18: =Calculations!BR281 -> 0 | BS18: 0 | BT18: =Calculations!BS281 -> 0 | BU18: =Calculations!BT281 -> 0 | BV18: =Calculations!BU281 -> 0 | BW18: =Calculations!BV281 -> 0 | BX18: =Calculations!BW281 -> 0 | BY18: =Calculations!BX281 -> 0 | BZ18: =Calculations!BY281 -> 0 | CA18: =Calculations!BZ281+Calculations!CA281 -> 0 | CB18: =Calculations!CB281 -> 0 | CC18: =Calculations!CC281 -> 0 | CD18: =Calculations!CD281 -> 0 | CE18: =Calculations!CE281 -> 0 | CF18: =SUM(C18:CE18) -> 7097.443 | CH18: 0
B19: Coke, refined petroleum, and nuclear fuel | C19: =Calculations!C282 -> 0 | D19: =Calculations!D282 -> 0 | E19: =Calculations!E282 -> 0 | F19: =Calculations!F282 -> 0 | G19: =Calculations!G282 -> 0 | H19: =Calculations!H282 -> 0 | I19: =Calculations!I282 -> 0 | J19: =Calculations!J282 -> 0 | ... BR19: =Calculations!BR282 -> 0 | BS19: 0 | BT19: =Calculations!BS282 -> 0 | BU19: =Calculations!BT282 -> 0 | BV19: =Calculations!BU282 -> 0 | BW19: =Calculations!BV282 -> 0 | BX19: =Calculations!BW282 -> 0 | BY19: =Calculations!BX282 -> 0 | BZ19: =Calculations!BY282 -> 0 | CA19: =Calculations!BZ282+Calculations!CA282 -> 0 | CB19: =Calculations!CB282 -> 0 | CC19: =Calculations!CC282 -> 0 | CD19: =Calculations!CD282 -> 0 | CE19: =Calculations!CE282 -> 0 | CF19: =SUM(C19:CE19) -> 28389.412 | CH19: 0
B20: Chemicals and chemical products | C20: =Calculations!C283 -> 0 | D20: =Calculations!D283 -> 0 | E20: =Calculations!E283 -> 0 | F20: =Calculations!F283 -> 0 | G20: =Calculations!G283 -> 0 | H20: =Calculations!H283 -> 0 | I20: =Calculations!I283 -> 0 | J20: =Calculations!J283 -> 0 | ... BR20: =Calculations!BR283 -> 0 | BS20: 0 | BT20: =Calculations!BS283 -> 0 | BU20: =Calculations!BT283 -> 0 | BV20: =Calculations!BU283 -> 0 | BW20: =Calculations!BV283 -> 0 | BX20: =Calculations!BW283 -> 0 | BY20: =Calculations!BX283 -> 0 | BZ20: =Calculations!BY283 -> 0 | CA20: =Calculations!BZ283+Calculations!CA283 -> 0 | CB20: =Calculations!CB283 -> 0 | CC20: =Calculations!CC283 -> 0 | CD20: =Calculations!CD283 -> 0 | CE20: =Calculations!CE283 -> 0 | CF20: =SUM(C20:CE20) -> 13147.266 | CH20: 0
B21: Rubber and plastics | C21: =Calculations!C284 -> 0 | D21: =Calculations!D284 -> 0 | E21: =Calculations!E284 -> 0 | F21: =Calculations!F284 -> 0 | G21: =Calculations!G284 -> 0 | H21: =Calculations!H284 -> 0 | I21: =Calculations!I284 -> 0 | J21: =Calculations!J284 -> 0 | ... BR21: =Calculations!BR284 -> 0 | BS21: 0 | BT21: =Calculations!BS284 -> 0 | BU21: =Calculations!BT284 -> 0 | BV21: =Calculations!BU284 -> 0 | BW21: =Calculations!BV284 -> 0 | BX21: =Calculations!BW284 -> 0 | BY21: =Calculations!BX284 -> 0 | BZ21: =Calculations!BY284 -> 0 | CA21: =Calculations!BZ284+Calculations!CA284 -> 0 | CB21: =Calculations!CB284 -> 0 | CC21: =Calculations!CC284 -> 0 | CD21: =Calculations!CD284 -> 0 | CE21: =Calculations!CE284 -> 0 | CF21: =SUM(C21:CE21) -> 6406.529 | CH21: 0
B22: Other nonmetallic minerals | C22: =Calculations!C285 -> 0 | D22: =Calculations!D285 -> 0 | E22: =Calculations!E285 -> 0 | F22: =Calculations!F285 -> 0 | G22: =Calculations!G285 -> 0 | H22: =Calculations!H285 -> 0 | I22: =Calculations!I285 -> 0 | J22: =Calculations!J285 -> 0 | ... BR22: =Calculations!BR285 -> 0 | BS22: 0 | BT22: =Calculations!BS285 -> 0 | BU22: =Calculations!BT285 -> 0 | BV22: =Calculations!BU285 -> 0 | BW22: =Calculations!BV285 -> 0 | BX22: =Calculations!BW285 -> 0 | BY22: =Calculations!BX285 -> 0 | BZ22: =Calculations!BY285 -> 0 | CA22: =Calculations!BZ285+Calculations!CA285 -> 0 | CB22: =Calculations!CB285 -> 0 | CC22: =Calculations!CC285 -> 0 | CD22: =Calculations!CD285 -> 0 | CE22: =Calculations!CE285 -> 0 | CF22: =SUM(C22:CE22) -> 8147.143 | CH22: 0
B23: Basic metals and fabricated metal | C23: =Calculations!C286 -> 0 | D23: =Calculations!D286 -> 0 | E23: =Calculations!E286 -> 0 | F23: =Calculations!F286 -> 0 | G23: =Calculations!G286 -> 0 | H23: =Calculations!H286 -> 0 | I23: =Calculations!I286 -> 0 | J23: =Calculations!J286 -> 0 | ... BR23: =Calculations!BR286 -> 0 | BS23: 0 | BT23: =Calculations!BS286 -> 0 | BU23: =Calculations!BT286 -> 0 | BV23: =Calculations!BU286 -> 0 | BW23: =Calculations!BV286 -> 0 | BX23: =Calculations!BW286 -> 0 | BY23: =Calculations!BX286 -> 0 | BZ23: =Calculations!BY286 -> 0 | CA23: =Calculations!BZ286+Calculations!CA286 -> 0 | CB23: =Calculations!CB286 -> 0 | CC23: =Calculations!CC286 -> 0 | CD23: =Calculations!CD286 -> 0 | CE23: =Calculations!CE286 -> 0 | CF23: =SUM(C23:CE23) -> 38703.505 | CH23: 0
B24: Machinery, nec | C24: =Calculations!C287 -> 0 | D24: =Calculations!D287 -> 0 | E24: =Calculations!E287 -> 0 | F24: =Calculations!F287 -> 0 | G24: =Calculations!G287 -> 0 | H24: =Calculations!H287 -> 0 | I24: =Calculations!I287 -> 0 | J24: =Calculations!J287 -> 0 | ... BR24: =Calculations!BR287 -> 0 | BS24: 0 | BT24: =Calculations!BS287 -> 0 | BU24: =Calculations!BT287 -> 0 | BV24: =Calculations!BU287 -> 0 | BW24: =Calculations!BV287 -> 0 | BX24: =Calculations!BW287 -> 0 | BY24: =Calculations!BX287 -> 0 | BZ24: =Calculations!BY287 -> 0 | CA24: =Calculations!BZ287+Calculations!CA287 -> 0 | CB24: =Calculations!CB287 -> 0 | CC24: =Calculations!CC287 -> 0 | CD24: =Calculations!CD287 -> 0 | CE24: =Calculations!CE287 -> 0 | CF24: =SUM(C24:CE24) -> 7111.347 | CH24: 0
... B44: Private households with employed persons | C44: =Calculations!C307 -> 0 | D44: =Calculations!D307 -> 0 | E44: =Calculations!E307 -> 0 | F44: =Calculations!F307 -> 0 | G44: =Calculations!G307 -> 0 | H44: =Calculations!H307 -> 0 | I44: =Calculations!I307 -> 0 | J44: =Calculations!J307 -> 0 | ... BR44: =Calculations!BR307 -> 0 | BS44: 0 | BT44: =Calculations!BS307 -> 0 | BU44: =Calculations!BT307 -> 0 | BV44: =Calculations!BU307 -> 0 | BW44: =Calculations!BV307 -> 0 | BX44: =Calculations!BW307 -> 0 | BY44: =Calculations!BX307 -> 0 | BZ44: =Calculations!BY307 -> 0 | CA44: =Calculations!BZ307+Calculations!CA307 -> 0 | CB44: =Calculations!CB307 -> 0 | CC44: =Calculations!CC307 -> 0 | CD44: =Calculations!CD307 -> 0 | CE44: =Calculations!CE307 -> 0 | CF44: =SUM(C44:CE44) -> 1945.3419 | CH44: 0
